Workbook

Sheet Frequency
B2: TIER | E2: ODDS | F2: ODDS | G2: PRIZE | K2: % OF | M2: Prize Structure
B3: NUMBER | C3: WIN METHOD | D3: PRIZE | E3: UP | F3: DOWN | G3: COST | H3: HUMAN NAME | I3: 1 in X Odds | J3: COUNT | K3: PRIZE FUND | M3: Kentucky Lottery
B4: =Tiers!B3 -> 0 | C4: =Tiers!X3 -> 0||||||||| | D4: =Tiers!C3 -> 0 | E4: =F4-SUM(E5:E410) -> 1486523 | F4: 2000000 | G4: =E4*D4 -> 0 | H4: Non-Win | I4: =F4/E4 -> 1.3454215 | J4: =ROUND(IF(D4=0,($N$17*0.3),((((N$17*0.7)-(N$19*N$18)))*(E4/$N$14)+$N$19)),0) -> 1800 | M4: King Kong Jackpots(MMJ3) Standard
B5: =Tiers!B4 -> 1 | C5: =Tiers!X4 -> main-0||||||||| | D5: =Tiers!C4 -> 0.1 | E5: 48698 | F5: 2000000 | G5: =E5*D5 -> 4869.8 | H5: ='Data Analysis'!BK3 & " | " & 'Data Analysis'!BL3 -> Less than Stake | Single Win | I5: =F5/E5 -> 41.069448 | J5: =ROUND(IF(D5=0,($N$17*0.3),((((N$17*0.7)-(N$19*N$18)))*(E5/$N$14)+$N$19)),0) -> 173 | K5: =G5/N$9 -> 0.0030685058
B6: =Tiers!B5 -> 2 | C6: =Tiers!X5 -> main-1||||||||| | D6: =Tiers!C5 -> 0.2 | E6: 35002 | F6: 2000000 | G6: =E6*D6 -> 7000.4 | H6: ='Data Analysis'!BK4 & " | " & 'Data Analysis'!BL4 -> Less than Stake | Single Win | I6: =F6/E6 -> 57.139592 | J6: =ROUND(IF(D6=0,($N$17*0.3),((((N$17*0.7)-(N$19*N$18)))*(E6/$N$14)+$N$19)),0) -> 126 | K6: =G6/N$9 -> 0.0044110165 | M6: Odds Down (ticket quantity if pool based): | N6: 2000000
B7: =Tiers!B6 -> 3 | C7: =Tiers!X6 -> main-2||||||||| | D7: =Tiers!C6 -> 0.5 | E7: 20000 | F7: 2000000 | G7: =E7*D7 -> 10000 | H7: ='Data Analysis'!BK5 & " | " & 'Data Analysis'!BL5 -> Less than Stake | Single Win | I7: =F7/E7 -> 100 | J7: =ROUND(IF(D7=0,($N$17*0.3),((((N$17*0.7)-(N$19*N$18)))*(E7/$N$14)+$N$19)),0) -> 75 | K7: =G7/N$9 -> 0.006301092 | M7: Base: | N7: 1
B8: =Tiers!B7 -> 4 | C8: =Tiers!X7 -> main-3||||||||| | D8: =Tiers!C7 -> 1 | E8: 27000 | F8: 2000000 | G8: =E8*D8 -> 27000 | H8: ='Data Analysis'!BK6 & " | " & 'Data Analysis'!BL6 -> Stake Back | Single Win | I8: =F8/E8 -> 74.074074 | J8: =ROUND(IF(D8=0,($N$17*0.3),((((N$17*0.7)-(N$19*N$18)))*(E8/$N$14)+$N$19)),0) -> 99 | K8: =G8/N$9 -> 0.017012948 | M8: Revenus (if pool based): | N8: =N6*N7 -> 2000000
B9: =Tiers!B8 -> 5 | C9: =Tiers!X8 -> main-4||||||||| | D9: =Tiers!C8 -> 2 | E9: 5000 | F9: 2000000 | G9: =E9*D9 -> 10000 | H9: ='Data Analysis'!BK7 & " | " & 'Data Analysis'!BL7 -> Standard Win | Single Win | I9: =F9/E9 -> 400 | J9: =ROUND(IF(D9=0,($N$17*0.3),((((N$17*0.7)-(N$19*N$18)))*(E9/$N$14)+$N$19)),0) -> 23 | K9: =G9/N$9 -> 0.006301092 | M9: Prize Fund (if pool based): | N9: =SUM(G4:G410) -> 1587026.5
B10: =Tiers!B9 -> 6 | C10: =Tiers!X9 -> main-5||||||||| | D10: =Tiers!C9 -> 5 | E10: 1000 | F10: 2000000 | G10: =E10*D10 -> 5000 | H10: ='Data Analysis'!BK8 & " | " & 'Data Analysis'!BL8 -> Standard Win | Single Win | I10: =F10/E10 -> 2000 | J10: =ROUND(IF(D10=0,($N$17*0.3),((((N$17*0.7)-(N$19*N$18)))*(E10/$N$14)+$N$19)),0) -> 9 | K10: =G10/N$9 -> 0.003150546 | M10: RTP Setting | N10: 0.84
B11: =Tiers!B10 -> 7 | C11: =Tiers!X10 -> main-6||||||||| | D11: =Tiers!C10 -> 10 | E11: 188 | F11: 2000000 | G11: =E11*D11 -> 1880 | H11: ='Data Analysis'!BK9 & " | " & 'Data Analysis'!BL9 -> Big Win | Single Win | I11: =F11/E11 -> 10638.298 | J11: =ROUND(IF(D11=0,($N$17*0.3),((((N$17*0.7)-(N$19*N$18)))*(E11/$N$14)+$N$19)),0) -> 7 | K11: =G11/N$9 -> 0.0011846053 | M11: Base RTP: | N11: =G411/N8 -> 0.79351325
B12: =Tiers!B11 -> 8 | C12: =Tiers!X11 -> main-7||||||||| | D12: =Tiers!C11 -> 20 | E12: 50 | F12: 2000000 | G12: =E12*D12 -> 1000 | H12: ='Data Analysis'!BK10 & " | " & 'Data Analysis'!BL10 -> Big Win | Single Win | I12: =F12/E12 -> 40000 | J12: =ROUND(IF(D12=0,($N$17*0.3),((((N$17*0.7)-(N$19*N$18)))*(E12/$N$14)+$N$19)),0) -> 6 | K12: =G12/N$9 -> 0.0006301092 | M12: JP RTP: | N12: ='Progressive Jackpots'!C14+'Progressive Jackpots'!C21 -> 0.03
B13: =Tiers!B12 -> 9 | C13: =Tiers!X12 -> main-8||||||||| | D13: =Tiers!C12 -> 30 | E13: 10 | F13: 2000000 | G13: =E13*D13 -> 300 | H13: ='Data Analysis'!BK11 & " | " & 'Data Analysis'!BL11 -> Big Win | Single Win | I13: =F13/E13 -> 200000 | J13: =ROUND(IF(D13=0,($N$17*0.3),((((N$17*0.7)-(N$19*N$18)))*(E13/$N$14)+$N$19)),0) -> 6 | K13: =G13/N$9 -> 0.00018903276 | M13: Total RTP | N13: =N11+N12 -> 0.82351325
B14: =Tiers!B13 -> 10 | C14: =Tiers!X13 -> main-9||||||||| | D14: =Tiers!C13 -> 40 | E14: 5 | F14: 2000000 | G14: =E14*D14 -> 200 | H14: ='Data Analysis'!BK12 & " | " & 'Data Analysis'!BL12 -> Big Win | Single Win | I14: =F14/E14 -> 400000 | J14: =ROUND(IF(D14=0,($N$17*0.3),((((N$17*0.7)-(N$19*N$18)))*(E14/$N$14)+$N$19)),0) -> 6 | K14: =G14/N$9 -> 0.00012602184 | M14: Winning Tiers Freq: | N14: =SUM(E5:E410) -> 513477
B15: =Tiers!B14 -> 11 | C15: =Tiers!X14 -> main-10||||||||| | D15: =Tiers!C14 -> 1 | E15: 30152 | F15: 2000000 | G15: =E15*D15 -> 30152 | H15: ='Data Analysis'!BK13 & " | " & 'Data Analysis'!BL13 -> Stake Back | Single Win | I15: =F15/E15 -> 66.330592 | J15: =ROUND(IF(D15=0,($N$17*0.3),((((N$17*0.7)-(N$19*N$18)))*(E15/$N$14)+$N$19)),0) -> 110 | K15: =G15/N$9 -> 0.018999053 | M15: Hit Rate: | N15: =N6/N14 -> 3.8950138
B16: =Tiers!B15 -> 12 | C16: =Tiers!X15 -> main-11||||||||| | D16: =Tiers!C15 -> 2 | E16: 8400 | F16: 2000000 | G16: =E16*D16 -> 16800 | H16: ='Data Analysis'!BK14 & " | " & 'Data Analysis'!BL14 -> Standard Win | Single Win | I16: =F16/E16 -> 238.09524 | J16: =ROUND(IF(D16=0,($N$17*0.3),((((N$17*0.7)-(N$19*N$18)))*(E16/$N$14)+$N$19)),0) -> 35 | K16: =G16/N$9 -> 0.010585835
B17: =Tiers!B16 -> 13 | C17: =Tiers!X16 -> main-12||||||||| | D17: =Tiers!C16 -> 3 | E17: 1000 | F17: 2000000 | G17: =E17*D17 -> 3000 | H17: ='Data Analysis'!BK15 & " | " & 'Data Analysis'!BL15 -> Standard Win | Single Win | I17: =F17/E17 -> 2000 | J17: =ROUND(IF(D17=0,($N$17*0.3),((((N$17*0.7)-(N$19*N$18)))*(E17/$N$14)+$N$19)),0) -> 9 | K17: =G17/N$9 -> 0.0018903276 | M17: Approx Count: | N17: 6000
B18: =Tiers!B17 -> 14 | C18: =Tiers!X17 -> main-13||||||||| | D18: =Tiers!C17 -> 5 | E18: 941 | F18: 2000000 | G18: =E18*D18 -> 4705 | H18: ='Data Analysis'!BK16 & " | " & 'Data Analysis'!BL16 -> Standard Win | Single Win | I18: =F18/E18 -> 2125.3985 | J18: =ROUND(IF(D18=0,($N$17*0.3),((((N$17*0.7)-(N$19*N$18)))*(E18/$N$14)+$N$19)),0) -> 9 | K18: =G18/N$9 -> 0.0029646638 | M18: Winning Tiers | N18: =COUNT(E5:E410) -> 406
B19: =Tiers!B18 -> 15 | C19: =Tiers!X18 -> main-14||||||||| | D19: =Tiers!C18 -> 10 | E19: 10 | F19: 2000000 | G19: =E19*D19 -> 100 | H19: ='Data Analysis'!BK17 & " | " & 'Data Analysis'!BL17 -> Big Win | Single Win | I19: =F19/E19 -> 200000 | J19: =ROUND(IF(D19=0,($N$17*0.3),((((N$17*0.7)-(N$19*N$18)))*(E19/$N$14)+$N$19)),0) -> 6 | K19: =G19/N$9 -> 6.301092e-05 | M19: Min per tier | N19: 6
B20: =Tiers!B19 -> 16 | C20: =Tiers!X19 -> main-15||||||||| | D20: =Tiers!C19 -> 20 | E20: 5 | F20: 2000000 | G20: =E20*D20 -> 100 | H20: ='Data Analysis'!BK18 & " | " & 'Data Analysis'!BL18 -> Big Win | Single Win | I20: =F20/E20 -> 400000 | J20: =ROUND(IF(D20=0,($N$17*0.3),((((N$17*0.7)-(N$19*N$18)))*(E20/$N$14)+$N$19)),0) -> 6 | K20: =G20/N$9 -> 6.301092e-05
B21: =Tiers!B20 -> 17 | C21: =Tiers!X20 -> main-16||||||||| | D21: =Tiers!C20 -> 100 | E21: 2 | F21: 2000000 | G21: =E21*D21 -> 200 | H21: ='Data Analysis'!BK19 & " | " & 'Data Analysis'!BL19 -> Huge Win | Single Win | I21: =F21/E21 -> 1000000 | J21: =ROUND(IF(D21=0,($N$17*0.3),((((N$17*0.7)-(N$19*N$18)))*(E21/$N$14)+$N$19)),0) -> 6 | K21: =G21/N$9 -> 0.00012602184 | M21: PPS Source(if any) | N21: Same as the Vanilla Version
B22: =Tiers!B21 -> 18 | C22: =Tiers!X21 -> main-17||||||||| | D22: =Tiers!C21 -> 2 | E22: 20000 | F22: 2000000 | G22: =E22*D22 -> 40000 | H22: ='Data Analysis'!BK20 & " | " & 'Data Analysis'!BL20 -> Standard Win | Single Win | I22: =F22/E22 -> 100 | J22: =ROUND(IF(D22=0,($N$17*0.3),((((N$17*0.7)-(N$19*N$18)))*(E22/$N$14)+$N$19)),0) -> 75 | K22: =G22/N$9 -> 0.025204368 | M22: Difference: | N22: =N8*N10-N9 -> 92973.5
B23: =Tiers!B22 -> 19 | C23: =Tiers!X22 -> main-18||||||||| | D23: =Tiers!C22 -> 3 | E23: 1000 | F23: 2000000 | G23: =E23*D23 -> 3000 | H23: ='Data Analysis'!BK21 & " | " & 'Data Analysis'!BL21 -> Standard Win | Single Win | I23: =F23/E23 -> 2000 | J23: =ROUND(IF(D23=0,($N$17*0.3),((((N$17*0.7)-(N$19*N$18)))*(E23/$N$14)+$N$19)),0) -> 9 | K23: =G23/N$9 -> 0.0018903276
B24: =Tiers!B23 -> 20 | C24: =Tiers!X23 -> main-19||||||||| | D24: =Tiers!C23 -> 5 | E24: 500 | F24: 2000000 | G24: =E24*D24 -> 2500 | H24: ='Data Analysis'!BK22 & " | " & 'Data Analysis'!BL22 -> Standard Win | Single Win | I24: =F24/E24 -> 4000 | J24: =ROUND(IF(D24=0,($N$17*0.3),((((N$17*0.7)-(N$19*N$18)))*(E24/$N$14)+$N$19)),0) -> 8 | K24: =G24/N$9 -> 0.001575273
B25: =Tiers!B24 -> 21 | C25: =Tiers!X24 -> main-20||||||||| | D25: =Tiers!C24 -> 10 | E25: 100 | F25: 2000000 | G25: =E25*D25 -> 1000 | H25: ='Data Analysis'!BK23 & " | " & 'Data Analysis'!BL23 -> Big Win | Single Win | I25: =F25/E25 -> 20000 | J25: =ROUND(IF(D25=0,($N$17*0.3),((((N$17*0.7)-(N$19*N$18)))*(E25/$N$14)+$N$19)),0) -> 6 | K25: =G25/N$9 -> 0.0006301092
B26: =Tiers!B25 -> 22 | C26: =Tiers!X25 -> main-21||||||||| | D26: =Tiers!C25 -> 20 | E26: 10 | F26: 2000000 | G26: =E26*D26 -> 200 | H26: ='Data Analysis'!BK24 & " | " & 'Data Analysis'!BL24 -> Big Win | Single Win | I26: =F26/E26 -> 200000 | J26: =ROUND(IF(D26=0,($N$17*0.3),((((N$17*0.7)-(N$19*N$18)))*(E26/$N$14)+$N$19)),0) -> 6 | K26: =G26/N$9 -> 0.00012602184
B27: =Tiers!B26 -> 23 | C27: =Tiers!X26 -> main-22||||||||| | D27: =Tiers!C26 -> 100 | E27: 2 | F27: 2000000 | G27: =E27*D27 -> 200 | H27: ='Data Analysis'!BK25 & " | " & 'Data Analysis'!BL25 -> Huge Win | Single Win | I27: =F27/E27 -> 1000000 | J27: =ROUND(IF(D27=0,($N$17*0.3),((((N$17*0.7)-(N$19*N$18)))*(E27/$N$14)+$N$19)),0) -> 6 | K27: =G27/N$9 -> 0.00012602184
B28: =Tiers!B27 -> 24 | C28: =Tiers!X27 -> main-23||||||||| | D28: =Tiers!C27 -> 200 | E28: 1 | F28: 2000000 | G28: =E28*D28 -> 200 | H28: ='Data Analysis'!BK26 & " | " & 'Data Analysis'!BL26 -> Huge Win | Single Win | I28: =F28/E28 -> 2000000 | J28: =ROUND(IF(D28=0,($N$17*0.3),((((N$17*0.7)-(N$19*N$18)))*(E28/$N$14)+$N$19)),0) -> 6 | K28: =G28/N$9 -> 0.00012602184
B29: =Tiers!B28 -> 25 | C29: =Tiers!X28 -> main-24||||||||| | D29: =Tiers!C28 -> 3 | E29: 2800 | F29: 2000000 | G29: =E29*D29 -> 8400 | H29: ='Data Analysis'!BK27 & " | " & 'Data Analysis'!BL27 -> Standard Win | Single Win | I29: =F29/E29 -> 714.28571 | J29: =ROUND(IF(D29=0,($N$17*0.3),((((N$17*0.7)-(N$19*N$18)))*(E29/$N$14)+$N$19)),0) -> 16 | K29: =G29/N$9 -> 0.0052929173
B30: =Tiers!B29 -> 26 | C30: =Tiers!X29 -> main-25||||||||| | D30: =Tiers!C29 -> 5 | E30: 941 | F30: 2000000 | G30: =E30*D30 -> 4705 | H30: ='Data Analysis'!BK28 & " | " & 'Data Analysis'!BL28 -> Standard Win | Single Win | I30: =F30/E30 -> 2125.3985 | J30: =ROUND(IF(D30=0,($N$17*0.3),((((N$17*0.7)-(N$19*N$18)))*(E30/$N$14)+$N$19)),0) -> 9 | K30: =G30/N$9 -> 0.0029646638
B31: =Tiers!B30 -> 27 | C31: =Tiers!X30 -> main-26||||||||| | D31: =Tiers!C30 -> 10 | E31: 110 | F31: 2000000 | G31: =E31*D31 -> 1100 | H31: ='Data Analysis'!BK29 & " | " & 'Data Analysis'!BL29 -> Big Win | Single Win | I31: =F31/E31 -> 18181.818 | J31: =ROUND(IF(D31=0,($N$17*0.3),((((N$17*0.7)-(N$19*N$18)))*(E31/$N$14)+$N$19)),0) -> 6 | K31: =G31/N$9 -> 0.00069312012
B32: =Tiers!B31 -> 28 | C32: =Tiers!X31 -> main-27||||||||| | D32: =Tiers!C31 -> 20 | E32: 10 | F32: 2000000 | G32: =E32*D32 -> 200 | H32: ='Data Analysis'!BK30 & " | " & 'Data Analysis'!BL30 -> Big Win | Single Win | I32: =F32/E32 -> 200000 | J32: =ROUND(IF(D32=0,($N$17*0.3),((((N$17*0.7)-(N$19*N$18)))*(E32/$N$14)+$N$19)),0) -> 6 | K32: =G32/N$9 -> 0.00012602184
B33: =Tiers!B32 -> 29 | C33: =Tiers!X32 -> main-28||||||||| | D33: =Tiers!C32 -> 100 | E33: 5 | F33: 2000000 | G33: =E33*D33 -> 500 | H33: ='Data Analysis'!BK31 & " | " & 'Data Analysis'!BL31 -> Huge Win | Single Win | I33: =F33/E33 -> 400000 | J33: =ROUND(IF(D33=0,($N$17*0.3),((((N$17*0.7)-(N$19*N$18)))*(E33/$N$14)+$N$19)),0) -> 6 | K33: =G33/N$9 -> 0.0003150546
B34: =Tiers!B33 -> 30 | C34: =Tiers!X33 -> main-29||||||||| | D34: =Tiers!C33 -> 200 | E34: 2 | F34: 2000000 | G34: =E34*D34 -> 400 | H34: ='Data Analysis'!BK32 & " | " & 'Data Analysis'!BL32 -> Huge Win | Single Win | I34: =F34/E34 -> 1000000 | J34: =ROUND(IF(D34=0,($N$17*0.3),((((N$17*0.7)-(N$19*N$18)))*(E34/$N$14)+$N$19)),0) -> 6 | K34: =G34/N$9 -> 0.00025204368
... B410: =Tiers!B409 -> 406 | C410: =Tiers!X409 -> bonusC-8||||||||| | D410: =Tiers!C409 -> 500 | E410: 1 | F410: 2000000 | G410: =E410*D410 -> 500 | H410: ='Data Analysis'!BK408 & " | " & 'Data Analysis'!BL408 -> Huge Win | Bonus Game C | I410: =F410/E410 -> 2000000 | J410: =ROUND(IF(D410=0,($N$17*0.3),((((N$17*0.7)-(N$19*N$18)))*(E410/$N$14)+$N$19)),0) -> 6 | K410: =G410/N$9 -> 0.0003150546
E411: =SUM(E4:E410) -> 2000000 | G411: =SUM(G4:G410) -> 1587026.5 | K411: =SUM(K4:K410) -> 1

Sheet Progressive Jackpots
B2: Base JP Odds Down | C2: 150000000 | E2: json setup form
B3: JP Stake | C3: 1 | E3: JP | F3: large1 | G3: large2
B4: Revenue | C4: =C2*C3 -> 150000000 | E4: initialAmount | F4: =N11 -> 225000 | G4: =N12 -> 225000
B5: Contribution | C5: =C3*C6 -> 0.03 | E5: increment | F5: =K18*100 -> 1.35 | G5: =K19*100 -> 1.35
B6: Contribution % | C6: =W15 -> 0.03
B7: Estimated plays per day | C7: 450000
B9: Seed | K9: =C6-C21 -> 0.003 | M9: BASE
B10: Number | C10: Name | D10: Bonus | E10: Prize | F10: Base Odds Up | G10: Odds Down | H10: Base 1 in x Odds | I10: Prize Cost | J10: Contribution split | K10: Contribution | M10: Odds Up | N10: Seed | O10: Target trigger | P10: Count | Q10: Odds Down | R10: 1 in x Odds | S10: Prize Cost | T10: Trigger minus Seed | U10: JP Contrib Cost | V10: Split (use on JP split above) | W10: Total JP Prize cost
B11: 1 | C11: large1 | D11: bonusA | E11: =N11 -> 225000 | F11: =C3*M11 -> 1 | G11: =C2 -> 150000000 | H11: =G11/F11 -> 150000000 | I11: =E11*F11 -> 225000 | J11: =I11/I14 -> 0.5 | K11: =S15*J11*C3 -> 0.0015 | M11: 1 | N11: 225000 | O11: 2250000 | P11: 4 | Q11: =C2 -> 150000000 | R11: =Q11/F11 -> 150000000 | S11: =M11*E11 -> 225000 | T11: =O11-N11 -> 2025000 | U11: =T11*M11 -> 2025000 | V11: =U11/U14 -> 0.5 | W11: =O11*M11 -> 2250000
B12: 2 | C12: large2 | D12: bonusB | E12: =N12 -> 225000 | F12: =C3*M12 -> 1 | G12: =C2 -> 150000000 | H12: =G12/F12 -> 150000000 | I12: =E12*F12 -> 225000 | J12: =I12/I14 -> 0.5 | K12: =S15*J12*C3 -> 0.0015 | M12: 1 | N12: 225000 | O12: 2250000 | P12: 4 | Q12: =C2 -> 150000000 | R12: =Q12/F12 -> 150000000 | S12: =M12*E12 -> 225000 | T12: =O12-N12 -> 2025000 | U12: =T12*M12 -> 2025000 | V12: =U12/U14 -> 0.5 | W12: =O12*M12 -> 2250000
B14: RTP | C14: =I14/C4 -> 0.003 | F14: =SUM(F11:F13) -> 2 | H14: =C2/F14 -> 75000000 | I14: =SUM(I11:I13) -> 450000 | J14: =SUM(J11:J13) -> 1 | K14: =SUM(K11:K13) -> 0.003 | M14: =SUM(M11:M13) -> 2 | S14: =SUM(S11:S13) -> 450000 | U14: =SUM(U11:U13) -> 4050000 | V14: =SUM(V11:V13) -> 1 | W14: =SUM(W11:W13) -> 4500000
S15: =S14/C2 -> 0.003 | U15: =U14/C2 -> 0.027 | W15: =W14/C2 -> 0.03
B16: Jackpot Contributions (excluding seed) | K16: =C6-C14 -> 0.027
B17: Number | C17: Name | D17: Bonus | E17: Average Prize | F17: Base Odds Up | G17: Odds Down | H17: Base 1 in x Odds | I17: Prize Cost | J17: Contribution split | K17: Contribution
B18: 1 | C18: large1 | D18: bonusA | E18: =K18*H18 -> 2025000 | F18: =C3*M11 -> 1 | G18: =C2 -> 150000000 | H18: =G18/F18 -> 150000000 | I18: =E18*F18 -> 2025000 | J18: =V11 -> 0.5 | K18: =U15*J18*C3 -> 0.0135
B19: 2 | C19: large2 | D19: bonusB | E19: =K19*H19 -> 2025000 | F19: =C3*M12 -> 1 | G19: =C2 -> 150000000 | H19: =G19/F19 -> 150000000 | I19: =E19*F19 -> 2025000 | J19: =V12 -> 0.5 | K19: =U15*J19*C3 -> 0.0135
B21: RTP | C21: =I21/C4 -> 0.027 | I21: =SUM(I18:I20) -> 4050000 | J21: =SUM(J18:J20) -> 1 | K21: =SUM(K18:K20) -> 0.027
B24: Overal Game Summary
B25: JP Event Prob | C25: =C2/F14 -> 75000000
B26: Total win Odds (JP+main) | C26: =1/((1/C25) + (1/Frequency!N15)) -> 3.8950136
B27: Total non-win Prob Up | C27: =Frequency!N6-(F14/(G12/Frequency!N6)+Frequency!N14) -> 1486523
B28: Total non-win Pob Down | C28: =Frequency!N6 -> 2000000
B29: main Game RTP | C29: =Frequency!N11 -> 0.79351325
B30: Seed contribution RTP | C30: =C14 -> 0.003
B31: JP Contribution RTP | C31: =C21 -> 0.027
B32: TOTAL | C32: =C29+C30+C31 -> 0.82351325

Sheet Delivery
B2: DIVISION | C2: METHOD | D2: PRIZE FACTOR | E2: PRICE POINT | F2: EXPECTED WINNERS PER CARD | G2: ODDS PER GRID | H2: TOTAL PRIZE | I2: PRIZE % | J2: PAYOUT % | L2: Prize Structure
L3: Kentucky Lottery
B4: 1 | C4: main-30||||||||| | D4: 1000 | E4: =D4*$M$7 -> 1000 | F4: 1 | G4: =$M$6/F4 -> 2000000 | H4: =F4*E4 -> 1000 | I4: =H4/$M$9 -> 0.0005952381 | J4: =H4/$M$8 -> 0.0005 | L4: King Kong Jackpots(MMJ3) Standard
B5: 2 | C5: bonusC-8||||||||| | D5: 500 | E5: =D5*$M$7 -> 500 | F5: 1 | G5: =$M$6/F5 -> 2000000 | H5: =F5*E5 -> 500 | I5: =H5/$M$9 -> 0.00029761905 | J5: =H5/$M$8 -> 0.00025
B6: 3 | C6: main-23||||||||| | D6: 200 | E6: =D6*$M$7 -> 200 | F6: 1 | G6: =$M$6/F6 -> 2000000 | H6: =F6*E6 -> 200 | I6: =H6/$M$9 -> 0.00011904762 | J6: =H6/$M$8 -> 0.0001 | L6: Odds Down (ticket quantity if pool based): | M6: 2000000
B7: 4 | C7: main-29||||||||| | D7: 200 | E7: =D7*$M$7 -> 200 | F7: 2 | G7: =$M$6/F7 -> 1000000 | H7: =F7*E7 -> 400 | I7: =H7/$M$9 -> 0.00023809524 | J7: =H7/$M$8 -> 0.0002 | L7: Base: | M7: 1
B8: 5 | C8: main-4|main-28|main-3|freeplayA-14|||||| | D8: 123.7 | E8: =D8*$M$7 -> 123.7 | F8: 2 | G8: =$M$6/F8 -> 1000000 | H8: =F8*E8 -> 247.4 | I8: =H8/$M$9 -> 0.0001472619 | J8: =H8/$M$8 -> 0.0001237 | L8: Revenus (if pool based): | M8: =M7*M6 -> 2000000
B9: 6 | C9: main-28|bonusA-5|||||||| | D9: 115 | E9: =D9*$M$7 -> 115 | F9: 5 | G9: =$M$6/F9 -> 400000 | H9: =F9*E9 -> 575 | I9: =H9/$M$9 -> 0.0003422619 | J9: =H9/$M$8 -> 0.0002875 | L9: Prize Fund (if pool based): | M9: =H411 -> 1680000
B10: 7 | C10: main-28|bonusB-5|||||||| | D10: 115 | E10: =D10*$M$7 -> 115 | F10: 5 | G10: =$M$6/F10 -> 400000 | H10: =F10*E10 -> 575 | I10: =H10/$M$9 -> 0.0003422619 | J10: =H10/$M$8 -> 0.0002875 | L10: RTP Setting | M10: 0.84
B11: 8 | C11: main-28|bonusC-5|||||||| | D11: 115 | E11: =D11*$M$7 -> 115 | F11: 5 | G11: =$M$6/F11 -> 400000 | H11: =F11*E11 -> 575 | I11: =H11/$M$9 -> 0.0003422619 | J11: =H11/$M$8 -> 0.0002875 | L11: Actual RTP: | M11: =M9/M8 -> 0.84
B12: 9 | C12: main-4|main-18|main-28|main-0|wild-15||||| | D12: 108.1 | E12: =D12*$M$7 -> 108.1 | F12: 2 | G12: =$M$6/F12 -> 1000000 | H12: =F12*E12 -> 216.2 | I12: =H12/$M$9 -> 0.00012869048 | J12: =H12/$M$8 -> 0.0001081 | L12: JP RTP: | M12: 0.03
B13: 10 | C13: main-4|main-28|main-3|wild-5|||||| | D13: 108 | E13: =D13*$M$7 -> 108 | F13: 3 | G13: =$M$6/F13 -> 666666.67 | H13: =F13*E13 -> 324 | I13: =H13/$M$9 -> 0.00019285714 | J13: =H13/$M$8 -> 0.000162 | L13: Total RTP: | M13: =M12+M11 -> 0.87
B14: 11 | C14: main-4|main-18|main-28|main-0|||||| | D14: 105.1 | E14: =D14*$M$7 -> 105.1 | F14: 2 | G14: =$M$6/F14 -> 1000000 | H14: =F14*E14 -> 210.2 | I14: =H14/$M$9 -> 0.00012511905 | J14: =H14/$M$8 -> 0.0001051 | L14: Winning Tiers Freq | M14: =SUM(F4:F409) -> 513477
B15: 12 | C15: main-4|main-28|main-3||||||| | D15: 103 | E15: =D15*$M$7 -> 103 | F15: 2 | G15: =$M$6/F15 -> 1000000 | H15: =F15*E15 -> 206 | I15: =H15/$M$9 -> 0.00012261905 | J15: =H15/$M$8 -> 0.000103 | L15: Hit Rate: | M15: =M6/M14 -> 3.8950138
B16: 13 | C16: main-16||||||||| | D16: 100 | E16: =D16*$M$7 -> 100 | F16: 2 | G16: =$M$6/F16 -> 1000000 | H16: =F16*E16 -> 200 | I16: =H16/$M$9 -> 0.00011904762 | J16: =H16/$M$8 -> 0.0001
B17: 14 | C17: main-22||||||||| | D17: 100 | E17: =D17*$M$7 -> 100 | F17: 2 | G17: =$M$6/F17 -> 1000000 | H17: =F17*E17 -> 200 | I17: =H17/$M$9 -> 0.00011904762 | J17: =H17/$M$8 -> 0.0001 | L17: The information contained in this document and all attached documents is strictly confidential and contains proprietary information. It is provided solely for use by the designated recipients and is subject to the terms of any confidentiality obligations or non-disclosure agreements between the parties. All other use is strictly prohibited.
B18: 15 | C18: main-28||||||||| | D18: 100 | E18: =D18*$M$7 -> 100 | F18: 5 | G18: =$M$6/F18 -> 400000 | H18: =F18*E18 -> 500 | I18: =H18/$M$9 -> 0.00029761905 | J18: =H18/$M$8 -> 0.00025
B19: 16 | C19: bonusA-10||||||||| | D19: 100 | E19: =D19*$M$7 -> 100 | F19: 50 | G19: =$M$6/F19 -> 40000 | H19: =F19*E19 -> 5000 | I19: =H19/$M$9 -> 0.0029761905 | J19: =H19/$M$8 -> 0.0025
B20: 17 | C20: bonusB-10||||||||| | D20: 100 | E20: =D20*$M$7 -> 100 | F20: 50 | G20: =$M$6/F20 -> 40000 | H20: =F20*E20 -> 5000 | I20: =H20/$M$9 -> 0.0029761905 | J20: =H20/$M$8 -> 0.0025
B21: 18 | C21: bonusC-7||||||||| | D21: 100 | E21: =D21*$M$7 -> 100 | F21: 50 | G21: =$M$6/F21 -> 40000 | H21: =F21*E21 -> 5000 | I21: =H21/$M$9 -> 0.0029761905 | J21: =H21/$M$8 -> 0.0025
B22: 19 | C22: main-4|main-14|main-15|wild-4|freeplayA-26||||| | D22: 60.2 | E22: =D22*$M$7 -> 60.2 | F22: 2 | G22: =$M$6/F22 -> 1000000 | H22: =F22*E22 -> 120.4 | I22: =H22/$M$9 -> 7.1666667e-05 | J22: =H22/$M$8 -> 6.02e-05
B23: 20 | C23: main-4|wild-9|bonusA-5||||||| | D23: 57 | E23: =D23*$M$7 -> 57 | F23: 2 | G23: =$M$6/F23 -> 1000000 | H23: =F23*E23 -> 114 | I23: =H23/$M$9 -> 6.7857143e-05 | J23: =H23/$M$8 -> 5.7e-05
B24: 21 | C24: main-4|wild-9|bonusB-5||||||| | D24: 57 | E24: =D24*$M$7 -> 57 | F24: 2 | G24: =$M$6/F24 -> 1000000 | H24: =F24*E24 -> 114 | I24: =H24/$M$9 -> 6.7857143e-05 | J24: =H24/$M$8 -> 5.7e-05
B25: 22 | C25: main-4|wild-9|bonusC-5||||||| | D25: 57 | E25: =D25*$M$7 -> 57 | F25: 2 | G25: =$M$6/F25 -> 1000000 | H25: =F25*E25 -> 114 | I25: =H25/$M$9 -> 6.7857143e-05 | J25: =H25/$M$8 -> 5.7e-05
B26: 23 | C26: freeplayA-31||||||||| | D26: 54.4 | E26: =D26*$M$7 -> 54.4 | F26: 10 | G26: =$M$6/F26 -> 200000 | H26: =F26*E26 -> 544 | I26: =H26/$M$9 -> 0.00032380952 | J26: =H26/$M$8 -> 0.000272
B27: 24 | C27: main-5|main-26|wild-14|freeplayA-24|||||| | D27: 51.7 | E27: =D27*$M$7 -> 51.7 | F27: 10 | G27: =$M$6/F27 -> 200000 | H27: =F27*E27 -> 517 | I27: =H27/$M$9 -> 0.0003077381 | J27: =H27/$M$8 -> 0.0002585
B28: 25 | C28: main-4|main-14|main-15|freeplayA-13|||||| | D28: 50.5 | E28: =D28*$M$7 -> 50.5 | F28: 2 | G28: =$M$6/F28 -> 1000000 | H28: =F28*E28 -> 101 | I28: =H28/$M$9 -> 6.0119048e-05 | J28: =H28/$M$8 -> 5.05e-05
B29: 26 | C29: bonusA-9||||||||| | D29: 50 | E29: =D29*$M$7 -> 50 | F29: 500 | G29: =$M$6/F29 -> 4000 | H29: =F29*E29 -> 25000 | I29: =H29/$M$9 -> 0.014880952 | J29: =H29/$M$8 -> 0.0125
... B409: 406 | C409: wild-0||||||||| | D409: 0.1 | E409: =D409*$M$7 -> 0.1 | F409: 25000 | G409: =$M$6/F409 -> 80 | H409: =F409*E409 -> 2500 | I409: =H409/$M$9 -> 0.0014880952 | J409: =H409/$M$8 -> 0.00125
B410: 407 | C410: Non Winning tickets | D410: 0 | E410: 0 | F410: 1486523 | G410: =$M$6/F410 -> 1.3454215 | H410: 0 | I410: 0 | J410: 0
F411: =SUM(F4:F410) -> 2000000 | H411: =SUM(H4:H410) -> 1680000 | I411: =SUM(I4:I410) -> 1 | J411: =SUM(J4:J410) -> 0.84
B413: Base JP Odds Down | C413: 150000000 | E413: json setup form
B414: JP Stake | C414: 1 | E414: JP | F414: large1 | G414: large2
B415: Revenue | C415: =C413*C414 -> 150000000 | E415: initialAmount | F415: =N422 -> 225000 | G415: =N423 -> 225000
B416: Contribution | C416: =C414*C417 -> 0.03 | E416: increment | F416: =K429*100 -> 1.35 | G416: =K430*100 -> 1.35
B417: Contribution % | C417: =W426 -> 0.03
B418: Estimated plays per day | C418: 450000
B420: Seed | K420: =C417-C432 -> 0.003 | M420: BASE
B421: Number | C421: Name | D421: Bonus | E421: Prize | F421: Base Odds Up | G421: Odds Down | H421: Base 1 in x Odds | I421: Prize Cost | J421: Contribution split | K421: Contribution | M421: Odds Up | N421: Seed | O421: Target trigger | P421: Count | Q421: Odds Down | R421: 1 in x Odds | S421: Prize Cost | T421: Trigger minus Seed | U421: JP Contrib Cost | V421: Split (use on JP split above) | W421: Total JP Prize cost
B422: 1 | C422: large1 | D422: bonusA | E422: =N422 -> 225000 | F422: =C414*M422 -> 1 | G422: =C413 -> 150000000 | H422: =G422/F422 -> 150000000 | I422: =E422*F422 -> 225000 | J422: =I422/I425 -> 0.5 | K422: =S426*J422*C414 -> 0.0015 | M422: 1 | N422: 225000 | O422: 2250000 | P422: 4 | Q422: =C413 -> 150000000 | R422: =Q422/F422 -> 150000000 | S422: =M422*E422 -> 225000 | T422: =O422-N422 -> 2025000 | U422: =T422*M422 -> 2025000 | V422: =U422/U425 -> 0.5 | W422: =O422*M422 -> 2250000
...

Sheet Odds Table
A1: Ticket Price | B1: 0.5 | C1: 1 in X Odds | D1: 1 | E1: 1 in X Odds | F1: 2 | G1: 1 in X Odds | H1: 5 | I1: 1 in X Odds | J1: 10 | K1: 1 in X Odds | L1: 20 | M1: 1 in X Odds | N1: 30 | O1: 1 in X Odds | P1: 50 | Q1: 1 in X Odds
A2: JP1 | B2: $225,000.00* | C2: =E2*($D$1/$B$1) -> 300000000 | D2: $225,000.00* | E2: 150000000 | F2: $225,000.00* | G2: =E2/F$1 -> 75000000 | H2: $225,000.00* | I2: =E2/H$1 -> 30000000 | J2: $225,000.00* | K2: =E2/J$1 -> 15000000 | L2: $225,000.00* | M2: =E2/L$1 -> 7500000 | N2: $225,000.00* | O2: =E2/N$1 -> 5000000 | P2: $225,000.00* | Q2: =E2/P$1 -> 3000000
A3: JP2 | B3: $225,000.00* | C3: =E3*($D$1/$B$1) -> 300000000 | D3: $225,000.00* | E3: 150000000 | F3: $225,000.00* | G3: =E3/F$1 -> 75000000 | H3: $225,000.00* | I3: =E3/H$1 -> 30000000 | J3: $225,000.00* | K3: =E3/J$1 -> 15000000 | L3: $225,000.00* | M3: =E3/L$1 -> 7500000 | N3: $225,000.00* | O3: =E3/N$1 -> 5000000 | P3: $225,000.00* | Q3: =E3/P$1 -> 3000000
A4: Prize | B4: =$D4*B$1 -> 500 | C4: =$E4 -> 2000000 | D4: 1000 | E4: 2000000 | F4: =$D4*F$1 -> 2000 | G4: =$E4 -> 2000000 | H4: =$D4*H$1 -> 5000 | I4: =$E4 -> 2000000 | J4: =$D4*J$1 -> 10000 | K4: =$E4 -> 2000000 | L4: =$D4*L$1 -> 20000 | M4: =$E4 -> 2000000 | N4: =$D4*N$1 -> 30000 | O4: =$E4 -> 2000000 | P4: =$D4*P$1 -> 50000 | Q4: =$E4 -> 2000000
B5: =$D5*B$1 -> 250 | C5: =$E5 -> 2000000 | D5: 500 | E5: 2000000 | F5: =$D5*F$1 -> 1000 | G5: =$E5 -> 2000000 | H5: =$D5*H$1 -> 2500 | I5: =$E5 -> 2000000 | J5: =$D5*J$1 -> 5000 | K5: =$E5 -> 2000000 | L5: =$D5*L$1 -> 10000 | M5: =$E5 -> 2000000 | N5: =$D5*N$1 -> 15000 | O5: =$E5 -> 2000000 | P5: =$D5*P$1 -> 25000 | Q5: =$E5 -> 2000000
B6: =$D6*B$1 -> 100 | C6: =$E6 -> 666666.67 | D6: 200 | E6: 666666.67 | F6: =$D6*F$1 -> 400 | G6: =$E6 -> 666666.67 | H6: =$D6*H$1 -> 1000 | I6: =$E6 -> 666666.67 | J6: =$D6*J$1 -> 2000 | K6: =$E6 -> 666666.67 | L6: =$D6*L$1 -> 4000 | M6: =$E6 -> 666666.67 | N6: =$D6*N$1 -> 6000 | O6: =$E6 -> 666666.67 | P6: =$D6*P$1 -> 10000 | Q6: =$E6 -> 666666.67
B7: =$D7*B$1 -> 61.85 | C7: =$E7 -> 1000000 | D7: 123.7 | E7: 1000000 | F7: =$D7*F$1 -> 247.4 | G7: =$E7 -> 1000000 | H7: =$D7*H$1 -> 618.5 | I7: =$E7 -> 1000000 | J7: =$D7*J$1 -> 1237 | K7: =$E7 -> 1000000 | L7: =$D7*L$1 -> 2474 | M7: =$E7 -> 1000000 | N7: =$D7*N$1 -> 3711 | O7: =$E7 -> 1000000 | P7: =$D7*P$1 -> 6185 | Q7: =$E7 -> 1000000
B8: =$D8*B$1 -> 57.5 | C8: =$E8 -> 133333.33 | D8: 115 | E8: 133333.33 | F8: =$D8*F$1 -> 230 | G8: =$E8 -> 133333.33 | H8: =$D8*H$1 -> 575 | I8: =$E8 -> 133333.33 | J8: =$D8*J$1 -> 1150 | K8: =$E8 -> 133333.33 | L8: =$D8*L$1 -> 2300 | M8: =$E8 -> 133333.33 | N8: =$D8*N$1 -> 3450 | O8: =$E8 -> 133333.33 | P8: =$D8*P$1 -> 5750 | Q8: =$E8 -> 133333.33
B9: =$D9*B$1 -> 54.05 | C9: =$E9 -> 1000000 | D9: 108.1 | E9: 1000000 | F9: =$D9*F$1 -> 216.2 | G9: =$E9 -> 1000000 | H9: =$D9*H$1 -> 540.5 | I9: =$E9 -> 1000000 | J9: =$D9*J$1 -> 1081 | K9: =$E9 -> 1000000 | L9: =$D9*L$1 -> 2162 | M9: =$E9 -> 1000000 | N9: =$D9*N$1 -> 3243 | O9: =$E9 -> 1000000 | P9: =$D9*P$1 -> 5405 | Q9: =$E9 -> 1000000
B10: =$D10*B$1 -> 54 | C10: =$E10 -> 666666.67 | D10: 108 | E10: 666666.67 | F10: =$D10*F$1 -> 216 | G10: =$E10 -> 666666.67 | H10: =$D10*H$1 -> 540 | I10: =$E10 -> 666666.67 | J10: =$D10*J$1 -> 1080 | K10: =$E10 -> 666666.67 | L10: =$D10*L$1 -> 2160 | M10: =$E10 -> 666666.67 | N10: =$D10*N$1 -> 3240 | O10: =$E10 -> 666666.67 | P10: =$D10*P$1 -> 5400 | Q10: =$E10 -> 666666.67
B11: =$D11*B$1 -> 52.55 | C11: =$E11 -> 1000000 | D11: 105.1 | E11: 1000000 | F11: =$D11*F$1 -> 210.2 | G11: =$E11 -> 1000000 | H11: =$D11*H$1 -> 525.5 | I11: =$E11 -> 1000000 | J11: =$D11*J$1 -> 1051 | K11: =$E11 -> 1000000 | L11: =$D11*L$1 -> 2102 | M11: =$E11 -> 1000000 | N11: =$D11*N$1 -> 3153 | O11: =$E11 -> 1000000 | P11: =$D11*P$1 -> 5255 | Q11: =$E11 -> 1000000
B12: =$D12*B$1 -> 51.5 | C12: =$E12 -> 1000000 | D12: 103 | E12: 1000000 | F12: =$D12*F$1 -> 206 | G12: =$E12 -> 1000000 | H12: =$D12*H$1 -> 515 | I12: =$E12 -> 1000000 | J12: =$D12*J$1 -> 1030 | K12: =$E12 -> 1000000 | L12: =$D12*L$1 -> 2060 | M12: =$E12 -> 1000000 | N12: =$D12*N$1 -> 3090 | O12: =$E12 -> 1000000 | P12: =$D12*P$1 -> 5150 | Q12: =$E12 -> 1000000
B13: =$D13*B$1 -> 50 | C13: =$E13 -> 12578.616 | D13: 100 | E13: 12578.616 | F13: =$D13*F$1 -> 200 | G13: =$E13 -> 12578.616 | H13: =$D13*H$1 -> 500 | I13: =$E13 -> 12578.616 | J13: =$D13*J$1 -> 1000 | K13: =$E13 -> 12578.616 | L13: =$D13*L$1 -> 2000 | M13: =$E13 -> 12578.616 | N13: =$D13*N$1 -> 3000 | O13: =$E13 -> 12578.616 | P13: =$D13*P$1 -> 5000 | Q13: =$E13 -> 12578.616
B14: =$D14*B$1 -> 30.1 | C14: =$E14 -> 1000000 | D14: 60.2 | E14: 1000000 | F14: =$D14*F$1 -> 120.4 | G14: =$E14 -> 1000000 | H14: =$D14*H$1 -> 301 | I14: =$E14 -> 1000000 | J14: =$D14*J$1 -> 602 | K14: =$E14 -> 1000000 | L14: =$D14*L$1 -> 1204 | M14: =$E14 -> 1000000 | N14: =$D14*N$1 -> 1806 | O14: =$E14 -> 1000000 | P14: =$D14*P$1 -> 3010 | Q14: =$E14 -> 1000000
B15: =$D15*B$1 -> 28.5 | C15: =$E15 -> 333333.33 | D15: 57 | E15: 333333.33 | F15: =$D15*F$1 -> 114 | G15: =$E15 -> 333333.33 | H15: =$D15*H$1 -> 285 | I15: =$E15 -> 333333.33 | J15: =$D15*J$1 -> 570 | K15: =$E15 -> 333333.33 | L15: =$D15*L$1 -> 1140 | M15: =$E15 -> 333333.33 | N15: =$D15*N$1 -> 1710 | O15: =$E15 -> 333333.33 | P15: =$D15*P$1 -> 2850 | Q15: =$E15 -> 333333.33
B16: =$D16*B$1 -> 27.2 | C16: =$E16 -> 200000 | D16: 54.4 | E16: 200000 | F16: =$D16*F$1 -> 108.8 | G16: =$E16 -> 200000 | H16: =$D16*H$1 -> 272 | I16: =$E16 -> 200000 | J16: =$D16*J$1 -> 544 | K16: =$E16 -> 200000 | L16: =$D16*L$1 -> 1088 | M16: =$E16 -> 200000 | N16: =$D16*N$1 -> 1632 | O16: =$E16 -> 200000 | P16: =$D16*P$1 -> 2720 | Q16: =$E16 -> 200000
... B180: =$D180*B$1 -> 0.05 | C180: =$E180 -> 27.137779 | D180: 0.1 | E180: 27.137779 | F180: =$D180*F$1 -> 0.2 | G180: =$E180 -> 27.137779 | H180: =$D180*H$1 -> 0.5 | I180: =$E180 -> 27.137779 | J180: =$D180*J$1 -> 1 | K180: =$E180 -> 27.137779 | L180: =$D180*L$1 -> 2 | M180: =$E180 -> 27.137779 | N180: =$D180*N$1 -> 3 | O180: =$E180 -> 27.137779 | P180: =$D180*P$1 -> 5 | Q180: =$E180 -> 27.137779
B181: NON WINNING | C181: =$E181 -> 1.3454215 | D181: NON WINNING | E181: 1.3454215 | F181: NON WINNING | G181: =$E181 -> 1.3454215 | H181: NON WINNING | I181: =$E181 -> 1.3454215 | J181: NON WINNING | K181: =$E181 -> 1.3454215 | L181: NON WINNING | M181: =$E181 -> 1.3454215 | N181: NON WINNING | O181: =$E181 -> 1.3454215 | P181: NON WINNING | Q181: =$E181 -> 1.3454215

Sheet Summary(Delivery)
A1: Size of Grid | B1: 0.5 | C1: 1 | D1: 2 | E1: 5 | F1: 10 | G1: 20 | H1: 30 | I1: 50
A2: Top Prize | B2: =$C$2*B$1 -> 500 | C2: 1000 | D2: =$C$2*D$1 -> 2000 | E2: =$C$2*E$1 -> 5000 | F2: =$C$2*F$1 -> 10000 | G2: =$C$2*G$1 -> 20000 | H2: =$C$2*H$1 -> 30000 | I2: =$C$2*I$1 -> 50000
A3: Version | B3: v1 | C3: v1 | D3: v1 | E3: v1 | F3: v1 | G3: v1 | H3: v1 | I3: v1
A4: Payout | B4: =$C$4 -> 0.84 | C4: 0.84 | D4: =$C$4 -> 0.84 | E4: =$C$4 -> 0.84 | F4: =$C$4 -> 0.84 | G4: =$C$4 -> 0.84 | H4: =$C$4 -> 0.84 | I4: =$C$4 -> 0.84
A5: Breakeven | B5: =$C$5 -> 0.047576 | C5: 0.047576 | D5: =$C$5 -> 0.047576 | E5: =$C$5 -> 0.047576 | F5: =$C$5 -> 0.047576 | G5: =$C$5 -> 0.047576 | H5: =$C$5 -> 0.047576 | I5: =$C$5 -> 0.047576
A6: Odds | B6: =$C$6 -> 3.8950138 | C6: 3.8950138 | D6: =$C$6 -> 3.8950138 | E6: =$C$6 -> 3.8950138 | F6: =$C$6 -> 3.8950138 | G6: =$C$6 -> 3.8950138 | H6: =$C$6 -> 3.8950138 | I6: =$C$6 -> 3.8950138
A7: Size of Grid | B7: 2000000 | C7: 2000000 | D7: 2000000 | E7: 2000000 | F7: 2000000 | G7: 2000000 | H7: 2000000 | I7: 2000000
A8: Low Tier Winning Range | B8: x0 - x5 | C8: x0 - x5 | D8: x0 - x5 | E8: x0 - x5 | F8: x0 - x5 | G8: x0 - x5 | H8: x0 - x5 | I8: x0 - x5
A9: Percentage in Low Tier | B9: =$C$9 -> 0.27970429 | C9: 0.27970429 | D9: =$C$9 -> 0.27970429 | E9: =$C$9 -> 0.27970429 | F9: =$C$9 -> 0.27970429 | G9: =$C$9 -> 0.27970429 | H9: =$C$9 -> 0.27970429 | I9: =$C$9 -> 0.27970429
A10: Medium Tier Winning Range | B10: x5 - x20 | C10: x5 - x20 | D10: x5 - x20 | E10: x5 - x20 | F10: x5 - x20 | G10: x5 - x20 | H10: x5 - x20 | I10: x5 - x20
A11: Percentage in Medium Tier | B11: =$C$11 -> 0.45495405 | C11: 0.45495405 | D11: =$C$11 -> 0.45495405 | E11: =$C$11 -> 0.45495405 | F11: =$C$11 -> 0.45495405 | G11: =$C$11 -> 0.45495405 | H11: =$C$11 -> 0.45495405 | I11: =$C$11 -> 0.45495405
A12: High Tier Winning Range | B12: x20 - top | C12: x20 - top | D12: x20 - top | E12: x20 - top | F12: x20 - top | G12: x20 - top | H12: x20 - top | I12: x20 - top
A13: Percentage in High Tier | B13: =$C$13 -> 0.26534167 | C13: 0.26534167 | D13: =$C$13 -> 0.26534167 | E13: =$C$13 -> 0.26534167 | F13: =$C$13 -> 0.26534167 | G13: =$C$13 -> 0.26534167 | H13: =$C$13 -> 0.26534167 | I13: =$C$13 -> 0.26534167
A14: Total Pool Amount | B14: =B7*B4*B1 -> 840000 | C14: =C7*C4*C1 -> 1680000 | D14: =D7*D4*D1 -> 3360000 | E14: =E7*E4*E1 -> 8400000 | F14: =F7*F4*F1 -> 16800000 | G14: =G7*G4*G1 -> 33600000 | H14: =H7*H4*H1 -> 50400000 | I14: =I7*I4*I1 -> 84000000
A15: Progressive Jackpot Info | B15: 0.5 | C15: 1 | D15: 2 | E15: 5 | F15: 10 | G15: 20 | H15: 30 | I15: 50
A16: Size of Grid | B16: 150000000 | C16: 150000000 | D16: 150000000 | E16: 150000000 | F16: 150000000 | G16: 150000000 | H16: 150000000 | I16: 150000000
A17: JP1 Wins/Grid | B17: =$C$17*B$15 -> 0.5 | C17: 1 | D17: =$C$17*D$15 -> 2 | E17: =$C$17*E$15 -> 5 | F17: =$C$17*F$15 -> 10 | G17: =$C$17*G$15 -> 20 | H17: =$C$17*H$15 -> 30 | I17: =$C$17*I$15 -> 50
A18: JP2 Wins/Grid | B18: =$C$18*B$15 -> 0.5 | C18: 1 | D18: =$C$18*D$15 -> 2 | E18: =$C$18*E$15 -> 5 | F18: =$C$18*F$15 -> 10 | G18: =$C$18*G$15 -> 20 | H18: =$C$18*H$15 -> 30 | I18: =$C$18*I$15 -> 50
A19: JP1 Wins/Price Ratio | B19: =$C$19 -> 1 | C19: 1 | D19: =$C$19 -> 1 | E19: =$C$19 -> 1 | F19: =$C$19 -> 1 | G19: =$C$19 -> 1 | H19: =$C$19 -> 1 | I19: =$C$19 -> 1
A20: JP2 Wins/Price Ratio | B20: =$C$20 -> 1 | C20: 1 | D20: =$C$20 -> 1 | E20: =$C$20 -> 1 | F20: =$C$20 -> 1 | G20: =$C$20 -> 1 | H20: =$C$20 -> 1 | I20: =$C$20 -> 1
A21: Odds of JP1 Win | B21: =$C$21/B$15 -> 300000000 | C21: 150000000 | D21: =$C$21/D$15 -> 75000000 | E21: =$C$21/E$15 -> 30000000 | F21: =$C$21/F$15 -> 15000000 | G21: =$C$21/G$15 -> 7500000 | H21: =$C$21/H$15 -> 5000000 | I21: =$C$21/I$15 -> 3000000
A22: Odds of JP2 Win | B22: =$C$22/B$15 -> 300000000 | C22: 150000000 | D22: =$C$22/D$15 -> 75000000 | E22: =$C$22/E$15 -> 30000000 | F22: =$C$22/F$15 -> 15000000 | G22: =$C$22/G$15 -> 7500000 | H22: =$C$22/H$15 -> 5000000 | I22: =$C$22/I$15 -> 3000000
A23: Revenue/JP win | B23: =B16*B15 -> 75000000 | C23: =C16*C15 -> 150000000 | D23: =D16*D15 -> 300000000 | E23: =E16*E15 -> 750000000 | F23: =F16*F15 -> 1500000000 | G23: =G16*G15 -> 3000000000 | H23: =H16*H15 -> 4500000000 | I23: =I16*I15 -> 7500000000
A24: Jackpot Reset % | B24: =$C$24 -> 0.003 | C24: 0.003 | D24: =$C$24 -> 0.003 | E24: =$C$24 -> 0.003 | F24: =$C$24 -> 0.003 | G24: =$C$24 -> 0.003 | H24: =$C$24 -> 0.003 | I24: =$C$24 -> 0.003
A25: JP1 Reset Value | B25: =$C$25 -> 225000 | C25: 225000 | D25: =$C$25 -> 225000 | E25: =$C$25 -> 225000 | F25: =$C$25 -> 225000 | G25: =$C$25 -> 225000 | H25: =$C$25 -> 225000 | I25: =$C$25 -> 225000
A26: JP2 Reset Value | B26: =$C$26 -> 225000 | C26: 225000 | D26: =$C$26 -> 225000 | E26: =$C$26 -> 225000 | F26: =$C$26 -> 225000 | G26: =$C$26 -> 225000 | H26: =$C$26 -> 225000 | I26: =$C$26 -> 225000
A27: Jackpot Increment % | B27: =$C$27 -> 0.027 | C27: 0.027 | D27: =$C$27 -> 0.027 | E27: =$C$27 -> 0.027 | F27: =$C$27 -> 0.027 | G27: =$C$27 -> 0.027 | H27: =$C$27 -> 0.027 | I27: =$C$27 -> 0.027
A28: Jackpot Increment Amount | B28: =B27*B15 -> 0.0135 | C28: =C27*C15 -> 0.027 | D28: =D27*D15 -> 0.054 | E28: =E27*E15 -> 0.135 | F28: =F27*F15 -> 0.27 | G28: =G27*G15 -> 0.54 | H28: =H27*H15 -> 0.81 | I28: =I27*I15 -> 1.35

Sheet Prize Breakdown
B2: Tier | C2: Win Methods | D2: Prize | E2: Symbol | F2: Quantity of Symbols
B3: 1 | C3: main-0 | D3: 0.1 | E3: 0,1,2,3 | F3: 3 | G3: A/B/C/D
B4: 2 | C4: main-1 | D4: 0.2 | E4: 0,1,2,3 | F4: 4 | G4: A/B/C/D
B5: 3 | C5: main-2 | D5: 0.5 | E5: 0,1,2,3 | F5: 5 | G5: A/B/C/D
B6: 4 | C6: main-3 | D6: 1 | E6: 0,1,2,3 | F6: 6 | G6: A/B/C/D
B7: 5 | C7: main-4 | D7: 2 | E7: 0,1,2,3 | F7: 7 | G7: A/B/C/D
B8: 6 | C8: main-5 | D8: 5 | E8: 0,1,2,3 | F8: 8 | G8: A/B/C/D | I8: A | J8: B | K8: C | L8: D | M8: E | N8: F | O8: G
B9: 7 | C9: main-6 | D9: 10 | E9: 0 | F9: 9 | H9: 3 | I9: 0.1 | J9: 0.1 | K9: 0.1 | L9: 0.1 | M9: 1 | N9: 2 | O9: 3
B10: 8 | C10: main-7 | D10: 20 | E10: 1 | F10: 9 | H10: 4 | I10: 0.2 | J10: 0.2 | K10: 0.2 | L10: 0.2 | M10: 2 | N10: 3 | O10: 5
B11: 9 | C11: main-8 | D11: 30 | E11: 2 | F11: 9 | H11: 5 | I11: 0.5 | J11: 0.5 | K11: 0.5 | L11: 0.5 | M11: 3 | N11: 5 | O11: 10
B12: 10 | C12: main-9 | D12: 40 | E12: 3 | F12: 9 | H12: 6 | I12: 1 | J12: 1 | K12: 1 | L12: 1 | M12: 5 | N12: 10 | O12: 20
B13: 11 | C13: main-10 | D13: 1 | E13: 4 | F13: 3 | H13: 7 | I13: 2 | J13: 2 | K13: 2 | L13: 2 | M13: 10 | N13: 20 | O13: 100
B14: 12 | C14: main-11 | D14: 2 | E14: 4 | F14: 4 | H14: 8 | I14: 5 | J14: 5 | K14: 5 | L14: 5 | M14: 20 | N14: 100 | O14: 200
B15: 13 | C15: main-12 | D15: 3 | E15: 4 | F15: 5 | H15: 9 | I15: 10 | J15: 20 | K15: 30 | L15: 40 | M15: 100 | N15: 200 | O15: 1000
B16: 14 | C16: main-13 | D16: 5 | E16: 4 | F16: 6
B17: 15 | C17: main-14 | D17: 10 | E17: 4 | F17: 7
B18: 16 | C18: main-15 | D18: 20 | E18: 4 | F18: 8
B19: 17 | C19: main-16 | D19: 100 | E19: 4 | F19: 9
B20: 18 | C20: main-17 | D20: 2 | E20: 5 | F20: 3
B21: 19 | C21: main-18 | D21: 3 | E21: 5 | F21: 4
B22: 20 | C22: main-19 | D22: 5 | E22: 5 | F22: 5
B23: 21 | C23: main-20 | D23: 10 | E23: 5 | F23: 6
B24: 22 | C24: main-21 | D24: 20 | E24: 5 | F24: 7
B25: 23 | C25: main-22 | D25: 100 | E25: 5 | F25: 8
B26: 24 | C26: main-23 | D26: 200 | E26: 5 | F26: 9
B27: 25 | C27: main-24 | D27: 3 | E27: 6 | F27: 3
... B33: 31 | C33: main-30 | D33: 1000 | E33: 6 | F33: 9
B34: 32 | C34: wild-0 | D34: 0.1 | E34: 0,1,2,3 | F34: 3 | G34: A/B/C/D
B35: 33 | C35: wild-1 | D35: 0.2 | E35: 0,1,2,3 | F35: 4 | G35: A/B/C/D
B36: 34 | C36: wild-2 | D36: 0.5 | E36: 0,1,2,3 | F36: 5 | G36: A/B/C/D
B37: 35 | C37: wild-3 | D37: 1 | E37: 0,1,2,3 | F37: 6 | G37: A/B/C/D
B38: 36 | C38: wild-4 | D38: 2 | E38: 0,1,2,3 | F38: 7 | G38: A/B/C/D
B39: 37 | C39: wild-5 | D39: 5 | E39: 0,1,2,3 | F39: 8 | G39: A/B/C/D
B40: 38 | C40: wild-6 | D40: 10 | E40: 0 | F40: 9
B41: 39 | C41: wild-7 | D41: 20 | E41: 1 | F41: 9
B42: 40 | C42: wild-8 | D42: 30 | E42: 2 | F42: 9
B43: 41 | C43: wild-9 | D43: 40 | E43: 3 | F43: 9
B44: 42 | C44: wild-10 | D44: 1 | E44: 4 | F44: 3
B45: 43 | C45: wild-11 | D45: 2 | E45: 4 | F45: 4
B46: 44 | C46: wild-12 | D46: 3 | E46: 4 | F46: 5
...

Sheet Summary
B3: ODDS DOWN (ticket quantity if pool based): | C3: 2000000
B4: BASE(ticket price): | C4: =Frequency!N7 -> 1
B5: REVENUE (if pool based): | C5: =C3*C4 -> 2000000
B6: Max prize | C6: =MAX(Tiers!C3:C4921) -> 1000
B7: Base RTP setting(JP exclude) | C7: =Frequency!N10 -> 0.84
B8: PRIZE FUND (if pool based): | C8: =C5*C7 -> 1680000
B9: Hit Rate | C9: =Summary!C3/(C3-Frequency!E4) -> 3.8950138
B10: Std. Dev. | C10: =('Data Analysis'!BM409/Summary!C3)^0.5 -> 3.510735
B12: wild Freq | C12: =Summary!C3/'Data Analysis'!AM409 -> 12.465875 | E12: Overall Feature Freq | F12: =C3/('Data Analysis'!AE409+'Data Analysis'!AF409) -> 57.053202
B13: wild Multi | C13: ='Data Analysis'!AN409/'Data Analysis'!AM409 -> 1.6053055 | E13: Overall Feature Avg. Multi | F13: =('Data Analysis'!BN409+'Data Analysis'!AG409)/('Data Analysis'!AE409+'Data Analysis'!AF409) -> 17.719681
B14: Standard wild Freq | C14: =C3/'Data Analysis'!AP409 -> 12.465875
B15: Standard wild Avg. Multi | C15: ='Data Analysis'!AQ409/'Data Analysis'!AP409 -> 1.6053055
B17: Freeplay Freq | C17: =Summary!C3/'Data Analysis'!AE409 -> 268.27632
B18: Freeplay Avg. Multi | C18: ='Data Analysis'!BN409/'Data Analysis'!AE409 -> 3.5505567
B19: Freeplay Value Share | C19: ='Data Analysis'!BN409/C8 -> 0.015755595
B21: bonus Freq | C21: =C3/('Data Analysis'!AY409+'Data Analysis'!BB409+'Data Analysis'!BE409) -> 27.89128
B22: bonus Multi | C22: =('Data Analysis'!BF409+'Data Analysis'!BC409+'Data Analysis'!AZ409)/('Data Analysis'!BE409+'Data Analysis'!BB409+'Data Analysis'!AY409) -> 14.556531
B23: bonus Value Share | C23: =('Data Analysis'!BF409+'Data Analysis'!BC409+'Data Analysis'!AZ409)/C8 -> 0.62131262
B24: bonusA Freq | C24: =C3/'Data Analysis'!AY409 -> 144.92754 | D24: Power Bonus
B25: bonusA Multi | C25: ='Data Analysis'!AZ409/'Data Analysis'!AY409 -> 21.546884
B26: bonusA Value Share | C26: ='Data Analysis'!AZ409/C8 -> 0.17699226
B27: bonusB Freq | C27: =C3/'Data Analysis'!BB409 -> 144.92754 | D27: Boost Bonus
B28: bonusB Multi | C28: ='Data Analysis'!BC409/'Data Analysis'!BB409 -> 21.546884
B29: bonusB Value Share | C29: ='Data Analysis'!BC409/C8 -> 0.17699226
B30: bonusC Freq | C30: =C3/'Data Analysis'!BE409 -> 45.344276 | D30: Barrel Stack
B31: bonusC Multi | C31: ='Data Analysis'!BF409/'Data Analysis'!BE409 -> 10.182311
B32: bonusC Value Share | C32: ='Data Analysis'!BF409/C8 -> 0.2673281
B35: instantA Freq | C35: =C3/'Data Analysis'!BH409 -> 465.11628
B36: instantA Multi | C36: ='Data Analysis'!BI409/'Data Analysis'!BH409 -> 6.1395349
B37: instantA Value Share | C37: ='Data Analysis'!BI409/C8 -> 0.015714286
G39: Odds Up | H39: %
B40: Combo Win Freq | C40: =C3/'Data Analysis'!AJ409 -> 22.652622 | E40: Single Feature | G40: ='Data Analysis'!BQ409+'Data Analysis'!BU409 -> 33352 | H40: =G40/G42 -> 0.9514192
B41: Combo Win Multi | C41: ='Data Analysis'!AK409/'Data Analysis'!AJ409 -> 1.9936607 | E41: Base game & Feature | G41: ='Data Analysis'!BS409+'Data Analysis'!BW409 -> 1703 | H41: =G41/G42 -> 0.048580802
G42: =SUM(G40:G41) -> 35055
B44: Category | C44: Freq | D44: Prob. | E44: Odds Dist. | F44: Value Dist. | G44: Hit Dist.
B45: NIL | C45: ='Data Analysis'!E2 -> 1486523 | D45: =C45/$C$56 -> 0.7432615 | E45: =1/D45 -> 1.3454215 | F45: - | G45: -
B46: >0 to <1 | C46: ='Data Analysis'!K409 -> 201550 | D46: =C46/$C$56 -> 0.100775 | E46: =1/D46 -> 9.923096 | F46: ='Data Analysis'!L409/Summary!C8 -> 0.031544167 | G46: =C46/SUM($C$46:$C$55) -> 0.39252002
B47: =1 -> 1 | C47: ='Data Analysis'!M409 -> 95322 | D47: =C47/$C$56 -> 0.047661 | E47: =1/D47 -> 20.981515 | F47: ='Data Analysis'!N409/Summary!C8 -> 0.056739286 | G47: =C47/SUM($C$46:$C$55) -> 0.18564025
B48: >1 to 2 | C48: ='Data Analysis'!O409 -> 108887 | D48: =C48/$C$56 -> 0.0544435 | E48: =1/D48 -> 18.367666 | F48: ='Data Analysis'!P409/Summary!C8 -> 0.1070578 | G48: =C48/SUM($C$46:$C$55) -> 0.21205818
B49: >2 to 5 | C49: ='Data Analysis'!Q409 -> 39268 | D49: =C49/$C$56 -> 0.019634 | E49: =1/D49 -> 50.932057 | F49: ='Data Analysis'!R409/Summary!C8 -> 0.091648393 | G49: =C49/SUM($C$46:$C$55) -> 0.076474701
...

Sheet Tiers
B2: Tier | C2: Total Prize | D2: Method 1 | E2: Prize 1 | F2: Method 2 | G2: Prize 2 | H2: Method 3 | I2: Prize 3 | J2: Method 4 | K2: Prize 4 | L2: Method 5 | M2: Prize 5 | N2: Method 6 | O2: Prize 6 | P2: Method 7 | Q2: Prize 7 | R2: Method 8 | S2: Prize 8 | T2: Method 9 | U2: Prize 9 | V2: Method 10 | W2: Prize 10 | X2: Method
B3: 0 | C3: =(E3+G3+I3+K3+M3+O3+Q3+S3+U3+W3) -> 0 | D3: 0 | E3: =VLOOKUP(D3,'Win Methods'!$C$4:$F$379,4,FALSE) -> 0 | G3: =VLOOKUP(F3,'Win Methods'!$C$4:$F$379,4,FALSE) -> 0 | I3: =VLOOKUP(H3,'Win Methods'!$C$4:$F$379,4,FALSE) -> 0 | K3: =VLOOKUP(J3,'Win Methods'!$C$4:$F$379,4,FALSE) -> 0 | M3: =VLOOKUP(L3,'Win Methods'!$C$4:$F$379,4,FALSE) -> 0 | O3: =VLOOKUP(N3,'Win Methods'!$C$4:$F$379,4,FALSE) -> 0 | Q3: =VLOOKUP(P3,'Win Methods'!$C$4:$F$379,4,FALSE) -> 0 | S3: =VLOOKUP(R3,'Win Methods'!$C$4:$F$379,4,FALSE) -> 0 | U3: =VLOOKUP(T3,'Win Methods'!$C$4:$F$379,4,FALSE) -> 0 | W3: =VLOOKUP(V3,'Win Methods'!$C$4:$F$379,4,FALSE) -> 0 | X3: =D3&"|"&F3&"|"&H3&"|"&J3&"|"&L3&"|"&N3&"|"&P3&"|"&R3&"|"&T3&"|"&V3 -> 0|||||||||
B4: 1 | C4: =(E4+G4+I4+K4+M4+O4+Q4+S4+U4+W4) -> 0.1 | D4: main-0 | E4: =VLOOKUP(D4,'Win Methods'!$C$4:$F$379,4,FALSE) -> 0.1 | G4: =VLOOKUP(F4,'Win Methods'!$C$4:$F$379,4,FALSE) -> 0 | I4: =VLOOKUP(H4,'Win Methods'!$C$4:$F$379,4,FALSE) -> 0 | K4: =VLOOKUP(J4,'Win Methods'!$C$4:$F$379,4,FALSE) -> 0 | M4: =VLOOKUP(L4,'Win Methods'!$C$4:$F$379,4,FALSE) -> 0 | O4: =VLOOKUP(N4,'Win Methods'!$C$4:$F$379,4,FALSE) -> 0 | Q4: =VLOOKUP(P4,'Win Methods'!$C$4:$F$379,4,FALSE) -> 0 | S4: =VLOOKUP(R4,'Win Methods'!$C$4:$F$379,4,FALSE) -> 0 | U4: =VLOOKUP(T4,'Win Methods'!$C$4:$F$379,4,FALSE) -> 0 | W4: =VLOOKUP(V4,'Win Methods'!$C$4:$F$379,4,FALSE) -> 0 | X4: =D4&"|"&F4&"|"&H4&"|"&J4&"|"&L4&"|"&N4&"|"&P4&"|"&R4&"|"&T4&"|"&V4 -> main-0|||||||||
B5: 2 | C5: =(E5+G5+I5+K5+M5+O5+Q5+S5+U5+W5) -> 0.2 | D5: main-1 | E5: =VLOOKUP(D5,'Win Methods'!$C$4:$F$379,4,FALSE) -> 0.2 | G5: =VLOOKUP(F5,'Win Methods'!$C$4:$F$379,4,FALSE) -> 0 | I5: =VLOOKUP(H5,'Win Methods'!$C$4:$F$379,4,FALSE) -> 0 | K5: =VLOOKUP(J5,'Win Methods'!$C$4:$F$379,4,FALSE) -> 0 | M5: =VLOOKUP(L5,'Win Methods'!$C$4:$F$379,4,FALSE) -> 0 | O5: =VLOOKUP(N5,'Win Methods'!$C$4:$F$379,4,FALSE) -> 0 | Q5: =VLOOKUP(P5,'Win Methods'!$C$4:$F$379,4,FALSE) -> 0 | S5: =VLOOKUP(R5,'Win Methods'!$C$4:$F$379,4,FALSE) -> 0 | U5: =VLOOKUP(T5,'Win Methods'!$C$4:$F$379,4,FALSE) -> 0 | W5: =VLOOKUP(V5,'Win Methods'!$C$4:$F$379,4,FALSE) -> 0 | X5: =D5&"|"&F5&"|"&H5&"|"&J5&"|"&L5&"|"&N5&"|"&P5&"|"&R5&"|"&T5&"|"&V5 -> main-1|||||||||
B6: 3 | C6: =(E6+G6+I6+K6+M6+O6+Q6+S6+U6+W6) -> 0.5 | D6: main-2 | E6: =VLOOKUP(D6,'Win Methods'!$C$4:$F$379,4,FALSE) -> 0.5 | G6: =VLOOKUP(F6,'Win Methods'!$C$4:$F$379,4,FALSE) -> 0 | I6: =VLOOKUP(H6,'Win Methods'!$C$4:$F$379,4,FALSE) -> 0 | K6: =VLOOKUP(J6,'Win Methods'!$C$4:$F$379,4,FALSE) -> 0 | M6: =VLOOKUP(L6,'Win Methods'!$C$4:$F$379,4,FALSE) -> 0 | O6: =VLOOKUP(N6,'Win Methods'!$C$4:$F$379,4,FALSE) -> 0 | Q6: =VLOOKUP(P6,'Win Methods'!$C$4:$F$379,4,FALSE) -> 0 | S6: =VLOOKUP(R6,'Win Methods'!$C$4:$F$379,4,FALSE) -> 0 | U6: =VLOOKUP(T6,'Win Methods'!$C$4:$F$379,4,FALSE) -> 0 | W6: =VLOOKUP(V6,'Win Methods'!$C$4:$F$379,4,FALSE) -> 0 | X6: =D6&"|"&F6&"|"&H6&"|"&J6&"|"&L6&"|"&N6&"|"&P6&"|"&R6&"|"&T6&"|"&V6 -> main-2|||||||||
B7: 4 | C7: =(E7+G7+I7+K7+M7+O7+Q7+S7+U7+W7) -> 1 | D7: main-3 | E7: =VLOOKUP(D7,'Win Methods'!$C$4:$F$379,4,FALSE) -> 1 | G7: =VLOOKUP(F7,'Win Methods'!$C$4:$F$379,4,FALSE) -> 0 | I7: =VLOOKUP(H7,'Win Methods'!$C$4:$F$379,4,FALSE) -> 0 | K7: =VLOOKUP(J7,'Win Methods'!$C$4:$F$379,4,FALSE) -> 0 | M7: =VLOOKUP(L7,'Win Methods'!$C$4:$F$379,4,FALSE) -> 0 | O7: =VLOOKUP(N7,'Win Methods'!$C$4:$F$379,4,FALSE) -> 0 | Q7: =VLOOKUP(P7,'Win Methods'!$C$4:$F$379,4,FALSE) -> 0 | S7: =VLOOKUP(R7,'Win Methods'!$C$4:$F$379,4,FALSE) -> 0 | U7: =VLOOKUP(T7,'Win Methods'!$C$4:$F$379,4,FALSE) -> 0 | W7: =VLOOKUP(V7,'Win Methods'!$C$4:$F$379,4,FALSE) -> 0 | X7: =D7&"|"&F7&"|"&H7&"|"&J7&"|"&L7&"|"&N7&"|"&P7&"|"&R7&"|"&T7&"|"&V7 -> main-3|||||||||
B8: 5 | C8: =(E8+G8+I8+K8+M8+O8+Q8+S8+U8+W8) -> 2 | D8: main-4 | E8: =VLOOKUP(D8,'Win Methods'!$C$4:$F$379,4,FALSE) -> 2 | G8: =VLOOKUP(F8,'Win Methods'!$C$4:$F$379,4,FALSE) -> 0 | I8: =VLOOKUP(H8,'Win Methods'!$C$4:$F$379,4,FALSE) -> 0 | K8: =VLOOKUP(J8,'Win Methods'!$C$4:$F$379,4,FALSE) -> 0 | M8: =VLOOKUP(L8,'Win Methods'!$C$4:$F$379,4,FALSE) -> 0 | O8: =VLOOKUP(N8,'Win Methods'!$C$4:$F$379,4,FALSE) -> 0 | Q8: =VLOOKUP(P8,'Win Methods'!$C$4:$F$379,4,FALSE) -> 0 | S8: =VLOOKUP(R8,'Win Methods'!$C$4:$F$379,4,FALSE) -> 0 | U8: =VLOOKUP(T8,'Win Methods'!$C$4:$F$379,4,FALSE) -> 0 | W8: =VLOOKUP(V8,'Win Methods'!$C$4:$F$379,4,FALSE) -> 0 | X8: =D8&"|"&F8&"|"&H8&"|"&J8&"|"&L8&"|"&N8&"|"&P8&"|"&R8&"|"&T8&"|"&V8 -> main-4|||||||||
B9: 6 | C9: =(E9+G9+I9+K9+M9+O9+Q9+S9+U9+W9) -> 5 | D9: main-5 | E9: =VLOOKUP(D9,'Win Methods'!$C$4:$F$379,4,FALSE) -> 5 | G9: =VLOOKUP(F9,'Win Methods'!$C$4:$F$379,4,FALSE) -> 0 | I9: =VLOOKUP(H9,'Win Methods'!$C$4:$F$379,4,FALSE) -> 0 | K9: =VLOOKUP(J9,'Win Methods'!$C$4:$F$379,4,FALSE) -> 0 | M9: =VLOOKUP(L9,'Win Methods'!$C$4:$F$379,4,FALSE) -> 0 | O9: =VLOOKUP(N9,'Win Methods'!$C$4:$F$379,4,FALSE) -> 0 | Q9: =VLOOKUP(P9,'Win Methods'!$C$4:$F$379,4,FALSE) -> 0 | S9: =VLOOKUP(R9,'Win Methods'!$C$4:$F$379,4,FALSE) -> 0 | U9: =VLOOKUP(T9,'Win Methods'!$C$4:$F$379,4,FALSE) -> 0 | W9: =VLOOKUP(V9,'Win Methods'!$C$4:$F$379,4,FALSE) -> 0 | X9: =D9&"|"&F9&"|"&H9&"|"&J9&"|"&L9&"|"&N9&"|"&P9&"|"&R9&"|"&T9&"|"&V9 -> main-5|||||||||
B10: 7 | C10: =(E10+G10+I10+K10+M10+O10+Q10+S10+U10+W10) -> 10 | D10: main-6 | E10: =VLOOKUP(D10,'Win Methods'!$C$4:$F$379,4,FALSE) -> 10 | G10: =VLOOKUP(F10,'Win Methods'!$C$4:$F$379,4,FALSE) -> 0 | I10: =VLOOKUP(H10,'Win Methods'!$C$4:$F$379,4,FALSE) -> 0 | K10: =VLOOKUP(J10,'Win Methods'!$C$4:$F$379,4,FALSE) -> 0 | M10: =VLOOKUP(L10,'Win Methods'!$C$4:$F$379,4,FALSE) -> 0 | O10: =VLOOKUP(N10,'Win Methods'!$C$4:$F$379,4,FALSE) -> 0 | Q10: =VLOOKUP(P10,'Win Methods'!$C$4:$F$379,4,FALSE) -> 0 | S10: =VLOOKUP(R10,'Win Methods'!$C$4:$F$379,4,FALSE) -> 0 | U10: =VLOOKUP(T10,'Win Methods'!$C$4:$F$379,4,FALSE) -> 0 | W10: =VLOOKUP(V10,'Win Methods'!$C$4:$F$379,4,FALSE) -> 0 | X10: =D10&"|"&F10&"|"&H10&"|"&J10&"|"&L10&"|"&N10&"|"&P10&"|"&R10&"|"&T10&"|"&V10 -> main-6|||||||||
B11: 8 | C11: =(E11+G11+I11+K11+M11+O11+Q11+S11+U11+W11) -> 20 | D11: main-7 | E11: =VLOOKUP(D11,'Win Methods'!$C$4:$F$379,4,FALSE) -> 20 | G11: =VLOOKUP(F11,'Win Methods'!$C$4:$F$379,4,FALSE) -> 0 | I11: =VLOOKUP(H11,'Win Methods'!$C$4:$F$379,4,FALSE) -> 0 | K11: =VLOOKUP(J11,'Win Methods'!$C$4:$F$379,4,FALSE) -> 0 | M11: =VLOOKUP(L11,'Win Methods'!$C$4:$F$379,4,FALSE) -> 0 | O11: =VLOOKUP(N11,'Win Methods'!$C$4:$F$379,4,FALSE) -> 0 | Q11: =VLOOKUP(P11,'Win Methods'!$C$4:$F$379,4,FALSE) -> 0 | S11: =VLOOKUP(R11,'Win Methods'!$C$4:$F$379,4,FALSE) -> 0 | U11: =VLOOKUP(T11,'Win Methods'!$C$4:$F$379,4,FALSE) -> 0 | W11: =VLOOKUP(V11,'Win Methods'!$C$4:$F$379,4,FALSE) -> 0 | X11: =D11&"|"&F11&"|"&H11&"|"&J11&"|"&L11&"|"&N11&"|"&P11&"|"&R11&"|"&T11&"|"&V11 -> main-7|||||||||
B12: 9 | C12: =(E12+G12+I12+K12+M12+O12+Q12+S12+U12+W12) -> 30 | D12: main-8 | E12: =VLOOKUP(D12,'Win Methods'!$C$4:$F$379,4,FALSE) -> 30 | G12: =VLOOKUP(F12,'Win Methods'!$C$4:$F$379,4,FALSE) -> 0 | I12: =VLOOKUP(H12,'Win Methods'!$C$4:$F$379,4,FALSE) -> 0 | K12: =VLOOKUP(J12,'Win Methods'!$C$4:$F$379,4,FALSE) -> 0 | M12: =VLOOKUP(L12,'Win Methods'!$C$4:$F$379,4,FALSE) -> 0 | O12: =VLOOKUP(N12,'Win Methods'!$C$4:$F$379,4,FALSE) -> 0 | Q12: =VLOOKUP(P12,'Win Methods'!$C$4:$F$379,4,FALSE) -> 0 | S12: =VLOOKUP(R12,'Win Methods'!$C$4:$F$379,4,FALSE) -> 0 | U12: =VLOOKUP(T12,'Win Methods'!$C$4:$F$379,4,FALSE) -> 0 | W12: =VLOOKUP(V12,'Win Methods'!$C$4:$F$379,4,FALSE) -> 0 | X12: =D12&"|"&F12&"|"&H12&"|"&J12&"|"&L12&"|"&N12&"|"&P12&"|"&R12&"|"&T12&"|"&V12 -> main-8|||||||||
B13: 10 | C13: =(E13+G13+I13+K13+M13+O13+Q13+S13+U13+W13) -> 40 | D13: main-9 | E13: =VLOOKUP(D13,'Win Methods'!$C$4:$F$379,4,FALSE) -> 40 | G13: =VLOOKUP(F13,'Win Methods'!$C$4:$F$379,4,FALSE) -> 0 | I13: =VLOOKUP(H13,'Win Methods'!$C$4:$F$379,4,FALSE) -> 0 | K13: =VLOOKUP(J13,'Win Methods'!$C$4:$F$379,4,FALSE) -> 0 | M13: =VLOOKUP(L13,'Win Methods'!$C$4:$F$379,4,FALSE) -> 0 | O13: =VLOOKUP(N13,'Win Methods'!$C$4:$F$379,4,FALSE) -> 0 | Q13: =VLOOKUP(P13,'Win Methods'!$C$4:$F$379,4,FALSE) -> 0 | S13: =VLOOKUP(R13,'Win Methods'!$C$4:$F$379,4,FALSE) -> 0 | U13: =VLOOKUP(T13,'Win Methods'!$C$4:$F$379,4,FALSE) -> 0 | W13: =VLOOKUP(V13,'Win Methods'!$C$4:$F$379,4,FALSE) -> 0 | X13: =D13&"|"&F13&"|"&H13&"|"&J13&"|"&L13&"|"&N13&"|"&P13&"|"&R13&"|"&T13&"|"&V13 -> main-9|||||||||
B14: 11 | C14: =(E14+G14+I14+K14+M14+O14+Q14+S14+U14+W14) -> 1 | D14: main-10 | E14: =VLOOKUP(D14,'Win Methods'!$C$4:$F$379,4,FALSE) -> 1 | G14: =VLOOKUP(F14,'Win Methods'!$C$4:$F$379,4,FALSE) -> 0 | I14: =VLOOKUP(H14,'Win Methods'!$C$4:$F$379,4,FALSE) -> 0 | K14: =VLOOKUP(J14,'Win Methods'!$C$4:$F$379,4,FALSE) -> 0 | M14: =VLOOKUP(L14,'Win Methods'!$C$4:$F$379,4,FALSE) -> 0 | O14: =VLOOKUP(N14,'Win Methods'!$C$4:$F$379,4,FALSE) -> 0 | Q14: =VLOOKUP(P14,'Win Methods'!$C$4:$F$379,4,FALSE) -> 0 | S14: =VLOOKUP(R14,'Win Methods'!$C$4:$F$379,4,FALSE) -> 0 | U14: =VLOOKUP(T14,'Win Methods'!$C$4:$F$379,4,FALSE) -> 0 | W14: =VLOOKUP(V14,'Win Methods'!$C$4:$F$379,4,FALSE) -> 0 | X14: =D14&"|"&F14&"|"&H14&"|"&J14&"|"&L14&"|"&N14&"|"&P14&"|"&R14&"|"&T14&"|"&V14 -> main-10|||||||||
B15: 12 | C15: =(E15+G15+I15+K15+M15+O15+Q15+S15+U15+W15) -> 2 | D15: main-11 | E15: =VLOOKUP(D15,'Win Methods'!$C$4:$F$379,4,FALSE) -> 2 | G15: =VLOOKUP(F15,'Win Methods'!$C$4:$F$379,4,FALSE) -> 0 | I15: =VLOOKUP(H15,'Win Methods'!$C$4:$F$379,4,FALSE) -> 0 | K15: =VLOOKUP(J15,'Win Methods'!$C$4:$F$379,4,FALSE) -> 0 | M15: =VLOOKUP(L15,'Win Methods'!$C$4:$F$379,4,FALSE) -> 0 | O15: =VLOOKUP(N15,'Win Methods'!$C$4:$F$379,4,FALSE) -> 0 | Q15: =VLOOKUP(P15,'Win Methods'!$C$4:$F$379,4,FALSE) -> 0 | S15: =VLOOKUP(R15,'Win Methods'!$C$4:$F$379,4,FALSE) -> 0 | U15: =VLOOKUP(T15,'Win Methods'!$C$4:$F$379,4,FALSE) -> 0 | W15: =VLOOKUP(V15,'Win Methods'!$C$4:$F$379,4,FALSE) -> 0 | X15: =D15&"|"&F15&"|"&H15&"|"&J15&"|"&L15&"|"&N15&"|"&P15&"|"&R15&"|"&T15&"|"&V15 -> main-11|||||||||
... B101: 98 | C101: =(E101+G101+I101+K101+M101+O101+Q101+S101+U101+W101) -> 0.2 | D101: freeplayA-44 | E101: =VLOOKUP(D101,'Win Methods'!$C$4:$F$379,4,FALSE) -> 0.2 | G101: =VLOOKUP(F101,'Win Methods'!$C$4:$F$379,4,FALSE) -> 0 | I101: =VLOOKUP(H101,'Win Methods'!$C$4:$F$379,4,FALSE) -> 0 | K101: =VLOOKUP(J101,'Win Methods'!$C$4:$F$379,4,FALSE) -> 0 | M101: =VLOOKUP(L101,'Win Methods'!$C$4:$F$379,4,FALSE) -> 0 | O101: =VLOOKUP(N101,'Win Methods'!$C$4:$F$379,4,FALSE) -> 0 | Q101: =VLOOKUP(P101,'Win Methods'!$C$4:$F$379,4,FALSE) -> 0 | S101: =VLOOKUP(R101,'Win Methods'!$C$4:$F$379,4,FALSE) -> 0 | U101: =VLOOKUP(T101,'Win Methods'!$C$4:$F$379,4,FALSE) -> 0 | W101: =VLOOKUP(V101,'Win Methods'!$C$4:$F$379,4,FALSE) -> 0 | X101: =D101&"|"&F101&"|"&H101&"|"&J101&"|"&L101&"|"&N101&"|"&P101&"|"&R101&"|"&T101&"|"&V101 -> freeplayA-44|||||||||
B102: 99 | C102: =(E102+G102+I102+K102+M102+O102+Q102+S102+U102+W102) -> 0.2 | D102: main-0 | E102: =VLOOKUP(D102,'Win Methods'!$C$4:$F$379,4,FALSE) -> 0.1 | F102: main-0 | G102: =VLOOKUP(F102,'Win Methods'!$C$4:$F$379,4,FALSE) -> 0.1 | I102: =VLOOKUP(H102,'Win Methods'!$C$4:$F$379,4,FALSE) -> 0 | K102: =VLOOKUP(J102,'Win Methods'!$C$4:$F$379,4,FALSE) -> 0 | M102: =VLOOKUP(L102,'Win Methods'!$C$4:$F$379,4,FALSE) -> 0 | O102: =VLOOKUP(N102,'Win Methods'!$C$4:$F$379,4,FALSE) -> 0 | Q102: =VLOOKUP(P102,'Win Methods'!$C$4:$F$379,4,FALSE) -> 0 | S102: =VLOOKUP(R102,'Win Methods'!$C$4:$F$379,4,FALSE) -> 0 | U102: =VLOOKUP(T102,'Win Methods'!$C$4:$F$379,4,FALSE) -> 0 | W102: =VLOOKUP(V102,'Win Methods'!$C$4:$F$379,4,FALSE) -> 0 | X102: =D102&"|"&F102&"|"&H102&"|"&J102&"|"&L102&"|"&N102&"|"&P102&"|"&R102&"|"&T102&"|"&V102 -> main-0|main-0||||||||
B103: 100 | C103: =(E103+G103+I103+K103+M103+O103+Q103+S103+U103+W103) -> 0.3 | D103: main-0 | E103: =VLOOKUP(D103,'Win Methods'!$C$4:$F$379,4,FALSE) -> 0.1 | F103: main-1 | G103: =VLOOKUP(F103,'Win Methods'!$C$4:$F$379,4,FALSE) -> 0.2 | I103: =VLOOKUP(H103,'Win Methods'!$C$4:$F$379,4,FALSE) -> 0 | K103: =VLOOKUP(J103,'Win Methods'!$C$4:$F$379,4,FALSE) -> 0 | M103: =VLOOKUP(L103,'Win Methods'!$C$4:$F$379,4,FALSE) -> 0 | O103: =VLOOKUP(N103,'Win Methods'!$C$4:$F$379,4,FALSE) -> 0 | Q103: =VLOOKUP(P103,'Win Methods'!$C$4:$F$379,4,FALSE) -> 0 | S103: =VLOOKUP(R103,'Win Methods'!$C$4:$F$379,4,FALSE) -> 0 | U103: =VLOOKUP(T103,'Win Methods'!$C$4:$F$379,4,FALSE) -> 0 | W103: =VLOOKUP(V103,'Win Methods'!$C$4:$F$379,4,FALSE) -> 0 | X103: =D103&"|"&F103&"|"&H103&"|"&J103&"|"&L103&"|"&N103&"|"&P103&"|"&R103&"|"&T103&"|"&V103 -> main-0|main-1||||||||
B104: 101 | C104: =(E104+G104+I104+K104+M104+O104+Q104+S104+U104+W104) -> 0.4 | D104: main-1 | E104: =VLOOKUP(D104,'Win Methods'!$C$4:$F$379,4,FALSE) -> 0.2 | F104: main-1 | G104: =VLOOKUP(F104,'Win Methods'!$C$4:$F$379,4,FALSE) -> 0.2 | I104: =VLOOKUP(H104,'Win Methods'!$C$4:$F$379,4,FALSE) -> 0 | K104: =VLOOKUP(J104,'Win Methods'!$C$4:$F$379,4,FALSE) -> 0 | M104: =VLOOKUP(L104,'Win Methods'!$C$4:$F$379,4,FALSE) -> 0 | O104: =VLOOKUP(N104,'Win Methods'!$C$4:$F$379,4,FALSE) -> 0 | Q104: =VLOOKUP(P104,'Win Methods'!$C$4:$F$379,4,FALSE) -> 0 | S104: =VLOOKUP(R104,'Win Methods'!$C$4:$F$379,4,FALSE) -> 0 | U104: =VLOOKUP(T104,'Win Methods'!$C$4:$F$379,4,FALSE) -> 0 | W104: =VLOOKUP(V104,'Win Methods'!$C$4:$F$379,4,FALSE) -> 0 | X104: =D104&"|"&F104&"|"&H104&"|"&J104&"|"&L104&"|"&N104&"|"&P104&"|"&R104&"|"&T104&"|"&V104 -> main-1|main-1||||||||
B105: 102 | C105: =(E105+G105+I105+K105+M105+O105+Q105+S105+U105+W105) -> 0.6 | D105: main-0 | E105: =VLOOKUP(D105,'Win Methods'!$C$4:$F$379,4,FALSE) -> 0.1 | F105: main-2 | G105: =VLOOKUP(F105,'Win Methods'!$C$4:$F$379,4,FALSE) -> 0.5 | I105: =VLOOKUP(H105,'Win Methods'!$C$4:$F$379,4,FALSE) -> 0 | K105: =VLOOKUP(J105,'Win Methods'!$C$4:$F$379,4,FALSE) -> 0 | M105: =VLOOKUP(L105,'Win Methods'!$C$4:$F$379,4,FALSE) -> 0 | O105: =VLOOKUP(N105,'Win Methods'!$C$4:$F$379,4,FALSE) -> 0 | Q105: =VLOOKUP(P105,'Win Methods'!$C$4:$F$379,4,FALSE) -> 0 | S105: =VLOOKUP(R105,'Win Methods'!$C$4:$F$379,4,FALSE) -> 0 | U105: =VLOOKUP(T105,'Win Methods'!$C$4:$F$379,4,FALSE) -> 0 | W105: =VLOOKUP(V105,'Win Methods'!$C$4:$F$379,4,FALSE) -> 0 | X105: =D105&"|"&F105&"|"&H105&"|"&J105&"|"&L105&"|"&N105&"|"&P105&"|"&R105&"|"&T105&"|"&V105 -> main-0|main-2||||||||
B106: 103 | C106: =(E106+G106+I106+K106+M106+O106+Q106+S106+U106+W106) -> 0.7 | D106: main-1 | E106: =VLOOKUP(D106,'Win Methods'!$C$4:$F$379,4,FALSE) -> 0.2 | F106: main-2 | G106: =VLOOKUP(F106,'Win Methods'!$C$4:$F$379,4,FALSE) -> 0.5 | I106: =VLOOKUP(H106,'Win Methods'!$C$4:$F$379,4,FALSE) -> 0 | K106: =VLOOKUP(J106,'Win Methods'!$C$4:$F$379,4,FALSE) -> 0 | M106: =VLOOKUP(L106,'Win Methods'!$C$4:$F$379,4,FALSE) -> 0 | O106: =VLOOKUP(N106,'Win Methods'!$C$4:$F$379,4,FALSE) -> 0 | Q106: =VLOOKUP(P106,'Win Methods'!$C$4:$F$379,4,FALSE) -> 0 | S106: =VLOOKUP(R106,'Win Methods'!$C$4:$F$379,4,FALSE) -> 0 | U106: =VLOOKUP(T106,'Win Methods'!$C$4:$F$379,4,FALSE) -> 0 | W106: =VLOOKUP(V106,'Win Methods'!$C$4:$F$379,4,FALSE) -> 0 | X106: =D106&"|"&F106&"|"&H106&"|"&J106&"|"&L106&"|"&N106&"|"&P106&"|"&R106&"|"&T106&"|"&V106 -> main-1|main-2||||||||
B107: 104 | C107: =(E107+G107+I107+K107+M107+O107+Q107+S107+U107+W107) -> 1.1 | D107: main-3 | E107: =VLOOKUP(D107,'Win Methods'!$C$4:$F$379,4,FALSE) -> 1 | F107: main-0 | G107: =VLOOKUP(F107,'Win Methods'!$C$4:$F$379,4,FALSE) -> 0.1 | I107: =VLOOKUP(H107,'Win Methods'!$C$4:$F$379,4,FALSE) -> 0 | K107: =VLOOKUP(J107,'Win Methods'!$C$4:$F$379,4,FALSE) -> 0 | M107: =VLOOKUP(L107,'Win Methods'!$C$4:$F$379,4,FALSE) -> 0 | O107: =VLOOKUP(N107,'Win Methods'!$C$4:$F$379,4,FALSE) -> 0 | Q107: =VLOOKUP(P107,'Win Methods'!$C$4:$F$379,4,FALSE) -> 0 | S107: =VLOOKUP(R107,'Win Methods'!$C$4:$F$379,4,FALSE) -> 0 | U107: =VLOOKUP(T107,'Win Methods'!$C$4:$F$379,4,FALSE) -> 0 | W107: =VLOOKUP(V107,'Win Methods'!$C$4:$F$379,4,FALSE) -> 0 | X107: =D107&"|"&F107&"|"&H107&"|"&J107&"|"&L107&"|"&N107&"|"&P107&"|"&R107&"|"&T107&"|"&V107 -> main-3|main-0||||||||
B108: 105 | C108: =(E108+G108+I108+K108+M108+O108+Q108+S108+U108+W108) -> 1.2 | D108: main-3 | E108: =VLOOKUP(D108,'Win Methods'!$C$4:$F$379,4,FALSE) -> 1 | F108: main-1 | G108: =VLOOKUP(F108,'Win Methods'!$C$4:$F$379,4,FALSE) -> 0.2 | I108: =VLOOKUP(H108,'Win Methods'!$C$4:$F$379,4,FALSE) -> 0 | K108: =VLOOKUP(J108,'Win Methods'!$C$4:$F$379,4,FALSE) -> 0 | M108: =VLOOKUP(L108,'Win Methods'!$C$4:$F$379,4,FALSE) -> 0 | O108: =VLOOKUP(N108,'Win Methods'!$C$4:$F$379,4,FALSE) -> 0 | Q108: =VLOOKUP(P108,'Win Methods'!$C$4:$F$379,4,FALSE) -> 0 | S108: =VLOOKUP(R108,'Win Methods'!$C$4:$F$379,4,FALSE) -> 0 | U108: =VLOOKUP(T108,'Win Methods'!$C$4:$F$379,4,FALSE) -> 0 | W108: =VLOOKUP(V108,'Win Methods'!$C$4:$F$379,4,FALSE) -> 0 | X108: =D108&"|"&F108&"|"&H108&"|"&J108&"|"&L108&"|"&N108&"|"&P108&"|"&R108&"|"&T108&"|"&V108 -> main-3|main-1||||||||
