Workbook

Sheet Frequency
B2: TIER | E2: ODDS | F2: ODDS | G2: PRIZE | K2: % OF | M2: Prize Structure
B3: NUMBER | C3: WIN METHOD | D3: PRIZE | E3: UP | F3: DOWN | G3: COST | H3: 1 in X odds | I3: HUMAN NAME | J3: COUNT | K3: PRIZE FUND | M3: Kentucky Lottery
B4: =Tiers!B3 -> 0 | C4: =Tiers!Y3 -> ||||||||| x 1 | D4: =Tiers!C3 -> 0 | E4: =F4-SUM(E5:E358) -> 1466392 | F4: =$N$6 -> 2000000 | G4: =E4*D4 -> 0 | H4: =F4/E4 -> 1.3638918 | I4: Non-Win | J4: =ROUND(IF(D4=0,($N$17*0.3),((((N$17*0.7)-(N$19*N$18)))*(E4/N$14)+$N$19)),0) -> 1800 | M4: Premium Gold(SSJ)
B5: =Tiers!B4 -> 1 | C5: =Tiers!Y4 -> main-0||||||||| x 1 | D5: =Tiers!C4 -> 0.1 | E5: 70000 | F5: =$N$6 -> 2000000 | G5: =E5*D5 -> 7000 | H5: =F5/E5 -> 28.571429 | I5: ='Data Analysis'!BM3 & " | " & 'Data Analysis'!BN3 -> Less than Stake | Single Win | J5: =ROUND(IF(D5=0,($N$17*0.3),((((N$17*0.7)-(N$19*N$18)))*(E5/N$14)+$N$19)),0) -> 278 | K5: =G5/N$9 -> 0.0042168675
B6: =Tiers!B5 -> 2 | C6: =Tiers!Y5 -> main-1||||||||| x 1 | D6: =Tiers!C5 -> 0.2 | E6: 40003 | F6: =$N$6 -> 2000000 | G6: =E6*D6 -> 8000.6 | H6: =F6/E6 -> 49.99625 | I6: ='Data Analysis'!BM4 & " | " & 'Data Analysis'!BN4 -> Less than Stake | Single Win | J6: =ROUND(IF(D6=0,($N$17*0.3),((((N$17*0.7)-(N$19*N$18)))*(E6/N$14)+$N$19)),0) -> 162 | K6: =G6/N$9 -> 0.0048196386 | M6: Odds Down (ticket quantity if pool based): | N6: 2000000
B7: =Tiers!B6 -> 3 | C7: =Tiers!Y6 -> main-2||||||||| x 1 | D7: =Tiers!C6 -> 0.5 | E7: 20001 | F7: =$N$6 -> 2000000 | G7: =E7*D7 -> 10000.5 | H7: =F7/E7 -> 99.995 | I7: ='Data Analysis'!BM5 & " | " & 'Data Analysis'!BN5 -> Less than Stake | Single Win | J7: =ROUND(IF(D7=0,($N$17*0.3),((((N$17*0.7)-(N$19*N$18)))*(E7/N$14)+$N$19)),0) -> 84 | K7: =G7/N$9 -> 0.0060243976 | M7: Base: | N7: 1
B8: =Tiers!B7 -> 4 | C8: =Tiers!Y7 -> main-3||||||||| x 1 | D8: =Tiers!C7 -> 1 | E8: 66424 | F8: =$N$6 -> 2000000 | G8: =E8*D8 -> 66424 | H8: =F8/E8 -> 30.109599 | I8: ='Data Analysis'!BM6 & " | " & 'Data Analysis'!BN6 -> Stake Back | Single Win | J8: =ROUND(IF(D8=0,($N$17*0.3),((((N$17*0.7)-(N$19*N$18)))*(E8/N$14)+$N$19)),0) -> 264 | K8: =G8/N$9 -> 0.040014458 | M8: Revenus (if pool based): | N8: =N6*N7 -> 2000000
B9: =Tiers!B8 -> 5 | C9: =Tiers!Y8 -> main-4||||||||| x 1 | D9: =Tiers!C8 -> 1.5 | E9: 30000 | F9: =$N$6 -> 2000000 | G9: =E9*D9 -> 45000 | H9: =F9/E9 -> 66.666667 | I9: ='Data Analysis'!BM7 & " | " & 'Data Analysis'!BN7 -> Standard Win | Single Win | J9: =ROUND(IF(D9=0,($N$17*0.3),((((N$17*0.7)-(N$19*N$18)))*(E9/N$14)+$N$19)),0) -> 123 | K9: =G9/N$9 -> 0.027108434 | M9: Prize Fund (if pool based): | N9: =G359 -> 1660000
B10: =Tiers!B9 -> 6 | C10: =Tiers!Y9 -> main-5||||||||| x 1 | D10: =Tiers!C9 -> 2 | E10: 15000 | F10: =$N$6 -> 2000000 | G10: =E10*D10 -> 30000 | H10: =F10/E10 -> 133.33333 | I10: ='Data Analysis'!BM8 & " | " & 'Data Analysis'!BN8 -> Standard Win | Single Win | J10: =ROUND(IF(D10=0,($N$17*0.3),((((N$17*0.7)-(N$19*N$18)))*(E10/N$14)+$N$19)),0) -> 64 | K10: =G10/N$9 -> 0.018072289 | M10: RTP Setting | N10: 0.83
B11: =Tiers!B10 -> 7 | C11: =Tiers!Y10 -> main-6||||||||| x 1 | D11: =Tiers!C10 -> 2.5 | E11: 3000 | F11: =$N$6 -> 2000000 | G11: =E11*D11 -> 7500 | H11: =F11/E11 -> 666.66667 | I11: ='Data Analysis'!BM9 & " | " & 'Data Analysis'!BN9 -> Standard Win | Single Win | J11: =ROUND(IF(D11=0,($N$17*0.3),((((N$17*0.7)-(N$19*N$18)))*(E11/N$14)+$N$19)),0) -> 18 | K11: =G11/N$9 -> 0.0045180723 | M11: Actual RTP: | N11: =N9/N8 -> 0.83 | O11: =IF(N11=N10, "okay", "error") -> okay
B12: =Tiers!B11 -> 8 | C12: =Tiers!Y11 -> main-7||||||||| x 1 | D12: =Tiers!C11 -> 3 | E12: 1000 | F12: =$N$6 -> 2000000 | G12: =E12*D12 -> 3000 | H12: =F12/E12 -> 2000 | I12: ='Data Analysis'!BM10 & " | " & 'Data Analysis'!BN10 -> Standard Win | Single Win | J12: =ROUND(IF(D12=0,($N$17*0.3),((((N$17*0.7)-(N$19*N$18)))*(E12/N$14)+$N$19)),0) -> 10 | K12: =G12/N$9 -> 0.0018072289 | M12: JP RTP: | N12: ='Progressive Jackpots'!C30+'Progressive Jackpots'!C31 -> 0.04
B13: =Tiers!B12 -> 9 | C13: =Tiers!Y12 -> main-8||||||||| x 1 | D13: =Tiers!C12 -> 5 | E13: 967 | F13: =$N$6 -> 2000000 | G13: =E13*D13 -> 4835 | H13: =F13/E13 -> 2068.2523 | I13: ='Data Analysis'!BM11 & " | " & 'Data Analysis'!BN11 -> Standard Win | Single Win | J13: =ROUND(IF(D13=0,($N$17*0.3),((((N$17*0.7)-(N$19*N$18)))*(E13/N$14)+$N$19)),0) -> 10 | K13: =G13/N$9 -> 0.0029126506 | M13: Total RTP: | N13: =N12+N11 -> 0.87
B14: =Tiers!B13 -> 10 | C14: =Tiers!Y13 -> main-9||||||||| x 1 | D14: =Tiers!C13 -> 10 | E14: 484 | F14: =$N$6 -> 2000000 | G14: =E14*D14 -> 4840 | H14: =F14/E14 -> 4132.2314 | I14: ='Data Analysis'!BM12 & " | " & 'Data Analysis'!BN12 -> Big Win | Single Win | J14: =ROUND(IF(D14=0,($N$17*0.3),((((N$17*0.7)-(N$19*N$18)))*(E14/N$14)+$N$19)),0) -> 8 | K14: =G14/N$9 -> 0.0029156627 | M14: Winning Tiers Freq | N14: =SUM(E5:E358) -> 533608
B15: =Tiers!B14 -> 11 | C15: =Tiers!Y14 -> main-10||||||||| x 1 | D15: =Tiers!C14 -> 1 | E15: 67382 | F15: =$N$6 -> 2000000 | G15: =E15*D15 -> 67382 | H15: =F15/E15 -> 29.681517 | I15: ='Data Analysis'!BM13 & " | " & 'Data Analysis'!BN13 -> Stake Back | Single Win | J15: =ROUND(IF(D15=0,($N$17*0.3),((((N$17*0.7)-(N$19*N$18)))*(E15/N$14)+$N$19)),0) -> 268 | K15: =G15/N$9 -> 0.040591566 | M15: Hit Rate: | N15: =N6/N14 -> 3.7480697
B16: =Tiers!B15 -> 12 | C16: =Tiers!Y15 -> main-11||||||||| x 1 | D16: =Tiers!C15 -> 1.5 | E16: 30000 | F16: =$N$6 -> 2000000 | G16: =E16*D16 -> 45000 | H16: =F16/E16 -> 66.666667 | I16: ='Data Analysis'!BM14 & " | " & 'Data Analysis'!BN14 -> Standard Win | Single Win | J16: =ROUND(IF(D16=0,($N$17*0.3),((((N$17*0.7)-(N$19*N$18)))*(E16/N$14)+$N$19)),0) -> 123 | K16: =G16/N$9 -> 0.027108434
B17: =Tiers!B16 -> 13 | C17: =Tiers!Y16 -> main-12||||||||| x 1 | D17: =Tiers!C16 -> 2 | E17: 15000 | F17: =$N$6 -> 2000000 | G17: =E17*D17 -> 30000 | H17: =F17/E17 -> 133.33333 | I17: ='Data Analysis'!BM15 & " | " & 'Data Analysis'!BN15 -> Standard Win | Single Win | J17: =ROUND(IF(D17=0,($N$17*0.3),((((N$17*0.7)-(N$19*N$18)))*(E17/N$14)+$N$19)),0) -> 64 | K17: =G17/N$9 -> 0.018072289 | M17: Approx Count: | N17: 6000
B18: =Tiers!B17 -> 14 | C18: =Tiers!Y17 -> main-13||||||||| x 1 | D18: =Tiers!C17 -> 5 | E18: 967 | F18: =$N$6 -> 2000000 | G18: =E18*D18 -> 4835 | H18: =F18/E18 -> 2068.2523 | I18: ='Data Analysis'!BM16 & " | " & 'Data Analysis'!BN16 -> Standard Win | Single Win | J18: =ROUND(IF(D18=0,($N$17*0.3),((((N$17*0.7)-(N$19*N$18)))*(E18/N$14)+$N$19)),0) -> 10 | K18: =G18/N$9 -> 0.0029126506 | M18: Winning Tiers | N18: =COUNT(E5:E358) -> 354
B19: =Tiers!B18 -> 15 | C19: =Tiers!Y18 -> main-14||||||||| x 1 | D19: =Tiers!C18 -> 10 | E19: 484 | F19: =$N$6 -> 2000000 | G19: =E19*D19 -> 4840 | H19: =F19/E19 -> 4132.2314 | I19: ='Data Analysis'!BM17 & " | " & 'Data Analysis'!BN17 -> Big Win | Single Win | J19: =ROUND(IF(D19=0,($N$17*0.3),((((N$17*0.7)-(N$19*N$18)))*(E19/N$14)+$N$19)),0) -> 8 | K19: =G19/N$9 -> 0.0029156627 | M19: Min per tier | N19: 6
B20: =Tiers!B19 -> 16 | C20: =Tiers!Y19 -> main-15||||||||| x 1 | D20: =Tiers!C19 -> 15 | E20: 323 | F20: =$N$6 -> 2000000 | G20: =E20*D20 -> 4845 | H20: =F20/E20 -> 6191.9505 | I20: ='Data Analysis'!BM18 & " | " & 'Data Analysis'!BN18 -> Big Win | Single Win | J20: =ROUND(IF(D20=0,($N$17*0.3),((((N$17*0.7)-(N$19*N$18)))*(E20/N$14)+$N$19)),0) -> 7 | K20: =G20/N$9 -> 0.0029186747
B21: =Tiers!B20 -> 17 | C21: =Tiers!Y20 -> main-16||||||||| x 1 | D21: =Tiers!C20 -> 20 | E21: 145 | F21: =$N$6 -> 2000000 | G21: =E21*D21 -> 2900 | H21: =F21/E21 -> 13793.103 | I21: ='Data Analysis'!BM19 & " | " & 'Data Analysis'!BN19 -> Big Win | Single Win | J21: =ROUND(IF(D21=0,($N$17*0.3),((((N$17*0.7)-(N$19*N$18)))*(E21/N$14)+$N$19)),0) -> 7 | K21: =G21/N$9 -> 0.001746988 | M21: Difference: | N21: =N8*N10-N9 -> 0
B22: =Tiers!B21 -> 18 | C22: =Tiers!Y21 -> main-17||||||||| x 1 | D22: =Tiers!C21 -> 50 | E22: 10 | F22: =$N$6 -> 2000000 | G22: =E22*D22 -> 500 | H22: =F22/E22 -> 200000 | I22: ='Data Analysis'!BM20 & " | " & 'Data Analysis'!BN20 -> Huge Win | Single Win | J22: =ROUND(IF(D22=0,($N$17*0.3),((((N$17*0.7)-(N$19*N$18)))*(E22/N$14)+$N$19)),0) -> 6 | K22: =G22/N$9 -> 0.00030120482 | M22: PPS Source(if any)
B23: =Tiers!B22 -> 19 | C23: =Tiers!Y22 -> main-18||||||||| x 1 | D23: =Tiers!C22 -> 100 | E23: 3 | F23: =$N$6 -> 2000000 | G23: =E23*D23 -> 300 | H23: =F23/E23 -> 666666.67 | I23: ='Data Analysis'!BM21 & " | " & 'Data Analysis'!BN21 -> Huge Win | Single Win | J23: =ROUND(IF(D23=0,($N$17*0.3),((((N$17*0.7)-(N$19*N$18)))*(E23/N$14)+$N$19)),0) -> 6 | K23: =G23/N$9 -> 0.00018072289
B24: =Tiers!B23 -> 20 | C24: =Tiers!Y23 -> main-19||||||||| x 1 | D24: =Tiers!C23 -> 200 | E24: 2 | F24: =$N$6 -> 2000000 | G24: =E24*D24 -> 400 | H24: =F24/E24 -> 1000000 | I24: ='Data Analysis'!BM22 & " | " & 'Data Analysis'!BN22 -> Huge Win | Single Win | J24: =ROUND(IF(D24=0,($N$17*0.3),((((N$17*0.7)-(N$19*N$18)))*(E24/N$14)+$N$19)),0) -> 6 | K24: =G24/N$9 -> 0.00024096386
B25: =Tiers!B24 -> 21 | C25: =Tiers!Y24 -> main-20||||||||| x 1 | D25: =Tiers!C24 -> 1.5 | E25: 30000 | F25: =$N$6 -> 2000000 | G25: =E25*D25 -> 45000 | H25: =F25/E25 -> 66.666667 | I25: ='Data Analysis'!BM23 & " | " & 'Data Analysis'!BN23 -> Standard Win | Single Win | J25: =ROUND(IF(D25=0,($N$17*0.3),((((N$17*0.7)-(N$19*N$18)))*(E25/N$14)+$N$19)),0) -> 123 | K25: =G25/N$9 -> 0.027108434 | M25: The information contained in this document and all attached documents is strictly confidential and contains proprietary information. It is provided solely for use by the designated recipients and is subject to the terms of any confidentiality obligations or non-disclosure agreements between the parties. All other use is strictly prohibited.
B26: =Tiers!B25 -> 22 | C26: =Tiers!Y25 -> main-21||||||||| x 1 | D26: =Tiers!C25 -> 2 | E26: 15000 | F26: =$N$6 -> 2000000 | G26: =E26*D26 -> 30000 | H26: =F26/E26 -> 133.33333 | I26: ='Data Analysis'!BM24 & " | " & 'Data Analysis'!BN24 -> Standard Win | Single Win | J26: =ROUND(IF(D26=0,($N$17*0.3),((((N$17*0.7)-(N$19*N$18)))*(E26/N$14)+$N$19)),0) -> 64 | K26: =G26/N$9 -> 0.018072289
B27: =Tiers!B26 -> 23 | C27: =Tiers!Y26 -> main-22||||||||| x 1 | D27: =Tiers!C26 -> 5 | E27: 1000 | F27: =$N$6 -> 2000000 | G27: =E27*D27 -> 5000 | H27: =F27/E27 -> 2000 | I27: ='Data Analysis'!BM25 & " | " & 'Data Analysis'!BN25 -> Standard Win | Single Win | J27: =ROUND(IF(D27=0,($N$17*0.3),((((N$17*0.7)-(N$19*N$18)))*(E27/N$14)+$N$19)),0) -> 10 | K27: =G27/N$9 -> 0.0030120482
B28: =Tiers!B27 -> 24 | C28: =Tiers!Y27 -> main-23||||||||| x 1 | D28: =Tiers!C27 -> 10 | E28: 500 | F28: =$N$6 -> 2000000 | G28: =E28*D28 -> 5000 | H28: =F28/E28 -> 4000 | I28: ='Data Analysis'!BM26 & " | " & 'Data Analysis'!BN26 -> Big Win | Single Win | J28: =ROUND(IF(D28=0,($N$17*0.3),((((N$17*0.7)-(N$19*N$18)))*(E28/N$14)+$N$19)),0) -> 8 | K28: =G28/N$9 -> 0.0030120482
B29: =Tiers!B28 -> 25 | C29: =Tiers!Y28 -> main-24||||||||| x 1 | D29: =Tiers!C28 -> 15 | E29: 320 | F29: =$N$6 -> 2000000 | G29: =E29*D29 -> 4800 | H29: =F29/E29 -> 6250 | I29: ='Data Analysis'!BM27 & " | " & 'Data Analysis'!BN27 -> Big Win | Single Win | J29: =ROUND(IF(D29=0,($N$17*0.3),((((N$17*0.7)-(N$19*N$18)))*(E29/N$14)+$N$19)),0) -> 7 | K29: =G29/N$9 -> 0.0028915663
B30: =Tiers!B29 -> 26 | C30: =Tiers!Y29 -> main-25||||||||| x 1 | D30: =Tiers!C29 -> 20 | E30: 142 | F30: =$N$6 -> 2000000 | G30: =E30*D30 -> 2840 | H30: =F30/E30 -> 14084.507 | I30: ='Data Analysis'!BM28 & " | " & 'Data Analysis'!BN28 -> Big Win | Single Win | J30: =ROUND(IF(D30=0,($N$17*0.3),((((N$17*0.7)-(N$19*N$18)))*(E30/N$14)+$N$19)),0) -> 7 | K30: =G30/N$9 -> 0.0017108434
B31: =Tiers!B30 -> 27 | C31: =Tiers!Y30 -> main-26||||||||| x 1 | D31: =Tiers!C30 -> 50 | E31: 10 | F31: =$N$6 -> 2000000 | G31: =E31*D31 -> 500 | H31: =F31/E31 -> 200000 | I31: ='Data Analysis'!BM29 & " | " & 'Data Analysis'!BN29 -> Huge Win | Single Win | J31: =ROUND(IF(D31=0,($N$17*0.3),((((N$17*0.7)-(N$19*N$18)))*(E31/N$14)+$N$19)),0) -> 6 | K31: =G31/N$9 -> 0.00030120482
B32: =Tiers!B31 -> 28 | C32: =Tiers!Y31 -> main-27||||||||| x 1 | D32: =Tiers!C31 -> 100 | E32: 3 | F32: =$N$6 -> 2000000 | G32: =E32*D32 -> 300 | H32: =F32/E32 -> 666666.67 | I32: ='Data Analysis'!BM30 & " | " & 'Data Analysis'!BN30 -> Huge Win | Single Win | J32: =ROUND(IF(D32=0,($N$17*0.3),((((N$17*0.7)-(N$19*N$18)))*(E32/N$14)+$N$19)),0) -> 6 | K32: =G32/N$9 -> 0.00018072289
B33: =Tiers!B32 -> 29 | C33: =Tiers!Y32 -> main-28||||||||| x 1 | D33: =Tiers!C32 -> 200 | E33: 2 | F33: =$N$6 -> 2000000 | G33: =E33*D33 -> 400 | H33: =F33/E33 -> 1000000 | I33: ='Data Analysis'!BM31 & " | " & 'Data Analysis'!BN31 -> Huge Win | Single Win | J33: =ROUND(IF(D33=0,($N$17*0.3),((((N$17*0.7)-(N$19*N$18)))*(E33/N$14)+$N$19)),0) -> 6 | K33: =G33/N$9 -> 0.00024096386
B34: =Tiers!B33 -> 30 | C34: =Tiers!Y33 -> main-29||||||||| x 1 | D34: =Tiers!C33 -> 500 | E34: 2 | F34: =$N$6 -> 2000000 | G34: =E34*D34 -> 1000 | H34: =F34/E34 -> 1000000 | I34: ='Data Analysis'!BM32 & " | " & 'Data Analysis'!BN32 -> Huge Win | Single Win | J34: =ROUND(IF(D34=0,($N$17*0.3),((((N$17*0.7)-(N$19*N$18)))*(E34/N$14)+$N$19)),0) -> 6 | K34: =G34/N$9 -> 0.00060240964
B35: =Tiers!B34 -> 31 | C35: =Tiers!Y34 -> main-30||||||||| x 1 | D35: =Tiers!C34 -> 2 | E35: 2416 | F35: =$N$6 -> 2000000 | G35: =E35*D35 -> 4832 | H35: =F35/E35 -> 827.81457 | I35: ='Data Analysis'!BM33 & " | " & 'Data Analysis'!BN33 -> Standard Win | Single Win | J35: =ROUND(IF(D35=0,($N$17*0.3),((((N$17*0.7)-(N$19*N$18)))*(E35/N$14)+$N$19)),0) -> 15 | K35: =G35/N$9 -> 0.0029108434
B36: =Tiers!B35 -> 32 | C36: =Tiers!Y35 -> main-31||||||||| x 1 | D36: =Tiers!C35 -> 5 | E36: 967 | F36: =$N$6 -> 2000000 | G36: =E36*D36 -> 4835 | H36: =F36/E36 -> 2068.2523 | I36: ='Data Analysis'!BM34 & " | " & 'Data Analysis'!BN34 -> Standard Win | Single Win | J36: =ROUND(IF(D36=0,($N$17*0.3),((((N$17*0.7)-(N$19*N$18)))*(E36/N$14)+$N$19)),0) -> 10 | K36: =G36/N$9 -> 0.0029126506
B37: =Tiers!B36 -> 33 | C37: =Tiers!Y36 -> main-32||||||||| x 1 | D37: =Tiers!C36 -> 10 | E37: 484 | F37: =$N$6 -> 2000000 | G37: =E37*D37 -> 4840 | H37: =F37/E37 -> 4132.2314 | I37: ='Data Analysis'!BM35 & " | " & 'Data Analysis'!BN35 -> Big Win | Single Win | J37: =ROUND(IF(D37=0,($N$17*0.3),((((N$17*0.7)-(N$19*N$18)))*(E37/N$14)+$N$19)),0) -> 8 | K37: =G37/N$9 -> 0.0029156627
... B358: =Tiers!B357 -> 354 | C358: =Tiers!Y357 -> bonusA-6||||||||| x 1 | D358: =Tiers!C357 -> 100 | E358: 100 | F358: =$N$6 -> 2000000 | G358: =E358*D358 -> 10000 | H358: =F358/E358 -> 20000 | I358: ='Data Analysis'!BM356 & " | " & 'Data Analysis'!BN356 -> Huge Win | Bonus Game A | J358: =ROUND(IF(D358=0,($N$17*0.3),((((N$17*0.7)-(N$19*N$18)))*(E358/N$14)+$N$19)),0) -> 6 | K358: =G358/N$9 -> 0.0060240964
E359: =SUM(E4:E358) -> 2000000 | G359: =SUM(G4:G358) -> 1660000 | K359: =SUM(K4:K358) -> 1

Sheet Progressive Jackpots
B2: Base JP Odds Down | C2: 50000000 | E2: json setup form
B3: JP Stake | C3: 1 | E3: JP | F3: small | G3: large
B4: Revenue | C4: =C2*C3 -> 50000000 | E4: initialAmount | F4: 2500 | G4: 150000
B5: Contribution | C5: =C3*C6 -> 0.04 | E5: increment | F5: =K18*100 -> 0.2 | G5: =K19*100 -> 3.3
B6: Contribution % | C6: =X13 -> 0.04
B7: Estimated plays per day | C7: 40000
M8: BASE
B9: Seed | K9: =C6-C21 -> 0.005 | M9: Odds Up | N9: Seed | O9: Target trigger | P9: Count | Q9: Odds Down | R9: 1 in x Odds | S9: Days to Trigger | T9: Prize Cost | U9: Trigger minus Seed | V9: JP Contrib Cost | W9: Split (use on JP split above) | X9: Total JP Prize cost
B10: Number | C10: Name | D10: Bonus | E10: Prize | F10: Base Odds Up | G10: Odds Down | H10: Base 1 in x Odds | I10: Prize Cost | J10: Contribution split | K10: Contribution | M10: 40 | N10: 2500 | O10: 5000 | P10: 4 | Q10: =C2 -> 50000000 | R10: =Q10/F11 -> 1250000 | S10: =R10/C7 -> 31.25 | T10: =M10*E11 -> 100000 | U10: =O10-N10 -> 2500 | V10: =U10*M10 -> 100000 | W10: =V10/V12 -> 0.057142857 | X10: =O10*M10 -> 200000
B11: 1 | C11: small | D11: A | E11: =N10 -> 2500 | F11: =C3*M10 -> 40 | G11: =C2 -> 50000000 | H11: =G11/F11 -> 1250000 | I11: =E11*F11 -> 100000 | J11: =I11/I14 -> 0.4 | K11: =T13*J11*C3 -> 0.002 | M11: 1 | N11: 150000 | O11: 1800000 | P11: 4 | Q11: =C2 -> 50000000 | R11: =Q11/F12 -> 50000000 | S11: =R11/C7 -> 1250 | T11: =E12*M11 -> 150000 | U11: =O11-N11 -> 1650000 | V11: =U11*M11 -> 1650000 | W11: =V11/V12 -> 0.94285714 | X11: =O11*M11 -> 1800000
B12: 2 | C12: large | D12: A | E12: =N11 -> 150000 | F12: =C3*M11 -> 1 | G12: =C2 -> 50000000 | H12: =G12/F12 -> 50000000 | I12: =E12*F12 -> 150000 | J12: =I12/I14 -> 0.6 | K12: =T13*J12*C3 -> 0.003 | M12: =SUM(M10:M11) -> 41 | R12: =SUM(R10:R11) -> 51250000 | T12: =SUM(T10:T11) -> 250000 | U12: =SUM(U10:U11) -> 1652500 | V12: =SUM(V10:V11) -> 1750000 | X12: =SUM(X10:X11) -> 2000000
T13: =T12/C2 -> 0.005 | V13: =V12/C2 -> 0.035 | X13: =X12/C2 -> 0.04
B14: RTP | C14: =I14/C4 -> 0.005 | F14: =SUM(F11:F12) -> 41 | H14: =C2/F14 -> 1219512.2 | I14: =SUM(I11:I12) -> 250000 | J14: =SUM(J11:J12) -> 1 | K14: =SUM(K11:K12) -> 0.005
B16: Jackpot Contributions (excluding seed) | K16: =C6-C14 -> 0.035
B17: Number | C17: Name | D17: Bonus | E17: Average Prize | F17: Base Odds Up | G17: Odds Down | H17: Base 1 in x Odds | I17: Prize Cost | J17: Contribution split | K17: Contribution
B18: 1 | C18: small | D18: A | E18: =K18*H18 -> 2500 | F18: =C3*M10 -> 40 | G18: =C2 -> 50000000 | H18: =G18/F18 -> 1250000 | I18: =E18*F18 -> 100000 | J18: =W10 -> 0.057142857 | K18: =V13*J18*C3 -> 0.002
B19: 2 | C19: large | D19: A | E19: =K19*H19 -> 1650000 | F19: =C3*M11 -> 1 | G19: =C2 -> 50000000 | H19: =G19/F19 -> 50000000 | I19: =E19*F19 -> 1650000 | J19: =W11 -> 0.94285714 | K19: =V13*J19*C3 -> 0.033
B21: RTP | C21: =I21/C4 -> 0.035 | I21: =SUM(I18:I19) -> 1750000 | J21: =SUM(J18:J19) -> 1 | K21: =SUM(K18:K19) -> 0.035
B24: Overal Game Summary
B25: JP Event Prob | C25: =C2/F14 -> 1219512.2
B26: Total win Odds (JP+Main) | C26: =1/((1/C25) + (1/Frequency!N15)) -> 3.7480582
B27: Total non-win Prob Up | C27: =Frequency!N6-(F14/(G12/Frequency!N6)+Frequency!N14) -> 1466390.4
B28: Total non-win Pob Down | C28: =Frequency!N6 -> 2000000
B29: Main Game RTP | C29: =Frequency!N11 -> 0.83
B30: Seed contribution RTP | C30: =C14 -> 0.005
B31: JP Contribution RTP | C31: =C21 -> 0.035
B32: TOTAL | C32: =C29+C30+C31 -> 0.87

Sheet Delivery
B2: DIVISION | C2: METHOD | D2: PRIZE FACTOR | E2: PRICE POINT | F2: EXPECTED WINNERS PER CARD | G2: ODDS PER GRID | H2: TOTAL PRIZE | I2: PRIZE % | J2: PAYOUT % | L2: Prize Structure
L3: Kentucky Lottery
B4: 1 | C4: main-39||||||||| x 1 | D4: 1000 | E4: =D4*$M$7 -> 1000 | F4: 1 | G4: =$M$6/F4 -> 2000000 | H4: =F4*E4 -> 1000 | I4: =H4/$M$9 -> 0.00060240964 | J4: =H4/$M$8 -> 0.0005 | L4: Premium Gold(SSJ)
B5: 2 | C5: main-29||||||||| x 1 | D5: 500 | E5: =D5*$M$7 -> 500 | F5: 2 | G5: =$M$6/F5 -> 1000000 | H5: =F5*E5 -> 1000 | I5: =H5/$M$9 -> 0.00060240964 | J5: =H5/$M$8 -> 0.0005
B6: 3 | C6: main-38||||||||| x 1 | D6: 500 | E6: =D6*$M$7 -> 500 | F6: 1 | G6: =$M$6/F6 -> 2000000 | H6: =F6*E6 -> 500 | I6: =H6/$M$9 -> 0.00030120482 | J6: =H6/$M$8 -> 0.00025 | L6: Odds Down (ticket quantity if pool based): | M6: 2000000
B7: 4 | C7: main-19||||||||| x 1 | D7: 200 | E7: =D7*$M$7 -> 200 | F7: 2 | G7: =$M$6/F7 -> 1000000 | H7: =F7*E7 -> 400 | I7: =H7/$M$9 -> 0.00024096386 | J7: =H7/$M$8 -> 0.0002 | L7: Base: | M7: 1
B8: 5 | C8: main-28||||||||| x 1 | D8: 200 | E8: =D8*$M$7 -> 200 | F8: 2 | G8: =$M$6/F8 -> 1000000 | H8: =F8*E8 -> 400 | I8: =H8/$M$9 -> 0.00024096386 | J8: =H8/$M$8 -> 0.0002 | L8: Revenus (if pool based): | M8: =M7*M6 -> 2000000
B9: 6 | C9: main-37||||||||| x 1 | D9: 200 | E9: =D9*$M$7 -> 200 | F9: 1 | G9: =$M$6/F9 -> 2000000 | H9: =F9*E9 -> 200 | I9: =H9/$M$9 -> 0.00012048193 | J9: =H9/$M$8 -> 0.0001 | L9: Prize Fund (if pool based): | M9: =H359 -> 1660000
B10: 7 | C10: main-13|freeplayA-7|||||||| x 20 | D10: 141.9 | E10: =D10*$M$7 -> 141.9 | F10: 2 | G10: =$M$6/F10 -> 1000000 | H10: =F10*E10 -> 283.8 | I10: =H10/$M$9 -> 0.00017096386 | J10: =H10/$M$8 -> 0.0001419 | L10: RTP Setting | M10: 0.83
B11: 8 | C11: main-13|bonusA-3|||||||| x 20 | D11: 125 | E11: =D11*$M$7 -> 125 | F11: 2 | G11: =$M$6/F11 -> 1000000 | H11: =F11*E11 -> 250 | I11: =H11/$M$9 -> 0.00015060241 | J11: =H11/$M$8 -> 0.000125 | L11: Actual RTP: | M11: =M9/M8 -> 0.83
B12: 9 | C12: main-15|bonusA-6|||||||| x 1 | D12: 115 | E12: =D12*$M$7 -> 115 | F12: 2 | G12: =$M$6/F12 -> 1000000 | H12: =F12*E12 -> 230 | I12: =H12/$M$9 -> 0.00013855422 | J12: =H12/$M$8 -> 0.000115 | L12: JP RTP: | M12: =C373+C380 -> 0.04
B13: 10 | C13: main-18||||||||| x 1 | D13: 100 | E13: =D13*$M$7 -> 100 | F13: 3 | G13: =$M$6/F13 -> 666666.67 | H13: =F13*E13 -> 300 | I13: =H13/$M$9 -> 0.00018072289 | J13: =H13/$M$8 -> 0.00015 | L13: Total RTP: | M13: =M12+M11 -> 0.87
B14: 11 | C14: main-27||||||||| x 1 | D14: 100 | E14: =D14*$M$7 -> 100 | F14: 3 | G14: =$M$6/F14 -> 666666.67 | H14: =F14*E14 -> 300 | I14: =H14/$M$9 -> 0.00018072289 | J14: =H14/$M$8 -> 0.00015 | L14: Winning Tiers Freq | M14: =SUM(F4:F357) -> 533608
B15: 12 | C15: main-36||||||||| x 1 | D15: 100 | E15: =D15*$M$7 -> 100 | F15: 3 | G15: =$M$6/F15 -> 666666.67 | H15: =F15*E15 -> 300 | I15: =H15/$M$9 -> 0.00018072289 | J15: =H15/$M$8 -> 0.00015 | L15: Hit Rate: | M15: =M6/M14 -> 3.7480697
B16: 13 | C16: main-13||||||||| x 20 | D16: 100 | E16: =D16*$M$7 -> 100 | F16: 2 | G16: =$M$6/F16 -> 1000000 | H16: =F16*E16 -> 200 | I16: =H16/$M$9 -> 0.00012048193 | J16: =H16/$M$8 -> 0.0001
B17: 14 | C17: bonusA-6||||||||| x 1 | D17: 100 | E17: =D17*$M$7 -> 100 | F17: 100 | G17: =$M$6/F17 -> 20000 | H17: =F17*E17 -> 10000 | I17: =H17/$M$9 -> 0.0060240964 | J17: =H17/$M$8 -> 0.005 | L17: The information contained in this document and all attached documents is strictly confidential and contains proprietary information. It is provided solely for use by the designated recipients and is subject to the terms of any confidentiality obligations or non-disclosure agreements between the parties. All other use is strictly prohibited.
B18: 15 | C18: main-2|main-3|main-10|freeplayA-7|||||| x 20 | D18: 91.9 | E18: =D18*$M$7 -> 91.9 | F18: 5 | G18: =$M$6/F18 -> 400000 | H18: =F18*E18 -> 459.5 | I18: =H18/$M$9 -> 0.00027680723 | J18: =H18/$M$8 -> 0.00022975
B19: 16 | C19: main-4|main-4|bonusA-4||||||| x 20 | D19: 90 | E19: =D19*$M$7 -> 90 | F19: 2 | G19: =$M$6/F19 -> 1000000 | H19: =F19*E19 -> 180 | I19: =H19/$M$9 -> 0.00010843373 | J19: =H19/$M$8 -> 9e-05
B20: 17 | C20: freeplayA-24||||||||| x 1 | D20: 87.9 | E20: =D20*$M$7 -> 87.9 | F20: 5 | G20: =$M$6/F20 -> 400000 | H20: =F20*E20 -> 439.5 | I20: =H20/$M$9 -> 0.00026475904 | J20: =H20/$M$8 -> 0.00021975
B21: 18 | C21: main-10|main-30|freeplayA-5||||||| x 20 | D21: 85.3 | E21: =D21*$M$7 -> 85.3 | F21: 6 | G21: =$M$6/F21 -> 333333.33 | H21: =F21*E21 -> 511.8 | I21: =H21/$M$9 -> 0.00030831325 | J21: =H21/$M$8 -> 0.0002559
B22: 19 | C22: main-10|main-30|bonusA-3||||||| x 20 | D22: 85 | E22: =D22*$M$7 -> 85 | F22: 2 | G22: =$M$6/F22 -> 1000000 | H22: =F22*E22 -> 170 | I22: =H22/$M$9 -> 0.00010240964 | J22: =H22/$M$8 -> 8.5e-05
B23: 20 | C23: main-21|freeplayA-9|||||||| x 20 | D23: 84.1 | E23: =D23*$M$7 -> 84.1 | F23: 5 | G23: =$M$6/F23 -> 400000 | H23: =F23*E23 -> 420.5 | I23: =H23/$M$9 -> 0.00025331325 | J23: =H23/$M$8 -> 0.00021025
B24: 21 | C24: main-2|main-20|freeplayA-9||||||| x 20 | D24: 84.1 | E24: =D24*$M$7 -> 84.1 | F24: 5 | G24: =$M$6/F24 -> 400000 | H24: =F24*E24 -> 420.5 | I24: =H24/$M$9 -> 0.00025331325 | J24: =H24/$M$8 -> 0.00021025
B25: 22 | C25: main-0|main-0|main-1|main-10|main-20|freeplayA-5|||| x 20 | D25: 83.3 | E25: =D25*$M$7 -> 83.3 | F25: 5 | G25: =$M$6/F25 -> 400000 | H25: =F25*E25 -> 416.5 | I25: =H25/$M$9 -> 0.00025090361 | J25: =H25/$M$8 -> 0.00020825
B26: 23 | C26: freeplayA-29||||||||| x 1 | D26: 81.5 | E26: =D26*$M$7 -> 81.5 | F26: 6 | G26: =$M$6/F26 -> 333333.33 | H26: =F26*E26 -> 489 | I26: =H26/$M$9 -> 0.00029457831 | J26: =H26/$M$8 -> 0.0002445
B27: 24 | C27: main-4|main-11|bonusA-2||||||| x 20 | D27: 80 | E27: =D27*$M$7 -> 80 | F27: 3 | G27: =$M$6/F27 -> 666666.67 | H27: =F27*E27 -> 240 | I27: =H27/$M$9 -> 0.00014457831 | J27: =H27/$M$8 -> 0.00012
B28: 25 | C28: main-2|main-3|main-10|bonusA-4|||||| x 20 | D28: 80 | E28: =D28*$M$7 -> 80 | F28: 3 | G28: =$M$6/F28 -> 666666.67 | H28: =F28*E28 -> 240 | I28: =H28/$M$9 -> 0.00014457831 | J28: =H28/$M$8 -> 0.00012
B29: 26 | C29: main-22|main-13|main-34|main-25|freeplayA-6||||| x 1 | D29: 79 | E29: =D29*$M$7 -> 79 | F29: 3 | G29: =$M$6/F29 -> 666666.67 | H29: =F29*E29 -> 237 | I29: =H29/$M$9 -> 0.00014277108 | J29: =H29/$M$8 -> 0.0001185
... B357: 354 | C357: main-0||||||||| x 1 | D357: 0.1 | E357: =D357*$M$7 -> 0.1 | F357: 70000 | G357: =$M$6/F357 -> 28.571429 | H357: =F357*E357 -> 7000 | I357: =H357/$M$9 -> 0.0042168675 | J357: =H357/$M$8 -> 0.0035
B358: 355 | C358: Non Winning tickets | D358: 0 | E358: =D358*$M$7 -> 0 | F358: =M6-M14 -> 1466392 | G358: =$M$6/F358 -> 1.3638918 | H358: =F358*E358 -> 0 | I358: =H358/$M$9 -> 0 | J358: =H358/$M$8 -> 0
F359: =SUM(F4:F358) -> 2000000 | H359: =SUM(H4:H358) -> 1660000 | I359: =SUM(I4:I358) -> 1 | J359: =SUM(J4:J358) -> 0.83
B361: Base JP Odds Down | C361: 50000000
B362: JP Stake | C362: =$M$7 -> 1
B363: Revenue | C363: =C361*C362 -> 50000000
B364: Contribution | C364: =C362*C365 -> 0.04
B365: Contribution % | C365: =X372 -> 0.04
B366: Estimated plays per day | C366: 40000
M367: BASE
B368: Seed | K368: =C365-C380 -> 0.005 | M368: Odds Up | N368: Seed | O368: Target trigger | P368: Count | Q368: Odds Down | R368: 1 in x Odds | S368: Days to Trigger | T368: Prize Cost | U368: Trigger minus Seed | V368: JP Contrib Cost | W368: Split (use on JP split above) | X368: Total JP Prize cost
B369: Number | C369: Name | D369: Bonus | E369: Prize | F369: Base Odds Up | G369: Odds Down | H369: Base 1 in x Odds | I369: Prize Cost | J369: Contribution split | K369: Contribution | M369: 40 | N369: 2500 | O369: 5000 | P369: 4 | Q369: =C361 -> 50000000 | R369: =Q369/F370 -> 1250000 | S369: =R369/C366 -> 31.25 | T369: =M369*E370 -> 100000 | U369: =O369-N369 -> 2500 | V369: =U369*M369 -> 100000 | W369: =V369/V371 -> 0.057142857 | X369: =O369*M369 -> 200000
...

Sheet Odds Table
A1: Ticket Price | B1: 0.5 | C1: 1 in X Odds | D1: 1 | E1: 1 in X Odds | F1: 2 | G1: 1 in X Odds | H1: 5 | I1: 1 in X Odds | J1: 10 | K1: 1 in X Odds | L1: 20 | M1: 1 in X Odds | N1: 30 | O1: 1 in X Odds | P1: 50 | Q1: 1 in X Odds
A2: JP1 | B2: $150,000.00* | C2: =E2*($D$1/$B$1) -> 100000000 | D2: $150,000.00* | E2: 50000000 | F2: $150,000.00* | G2: =E2/$F$1 -> 25000000 | H2: $150,000.00* | I2: =E2/$H$1 -> 10000000 | J2: $150,000.00* | K2: =E2/$J$1 -> 5000000 | L2: $150,000.00* | M2: =E2/$L$1 -> 2500000 | N2: $150,000.00* | O2: =E2/$N$1 -> 1666666.7 | P2: $150,000.00* | Q2: =E2/$P$1 -> 1000000
A3: JP2 | B3: $2,500.00* | C3: =E3*($D$1/$B$1) -> 2500000 | D3: $2,500.00* | E3: 1250000 | F3: $2,500.00* | G3: =E3/$F$1 -> 625000 | H3: $2,500.00* | I3: =E3/$H$1 -> 250000 | J3: $2,500.00* | K3: =E3/$J$1 -> 125000 | L3: $2,500.00* | M3: =E3/$L$1 -> 62500 | N3: $2,500.00* | O3: =E3/$N$1 -> 41666.667 | P3: $2,500.00* | Q3: =E3/$P$1 -> 25000
A4: Prize | B4: =D4*0.5 -> 500 | C4: =E4 -> 2000000 | D4: 1000 | E4: 2000000 | F4: =D4*2 -> 2000 | G4: =E4 -> 2000000 | H4: =D4*5 -> 5000 | I4: =E4 -> 2000000 | J4: =D4*10 -> 10000 | K4: =E4 -> 2000000 | L4: =D4*20 -> 20000 | M4: =K4 -> 2000000 | N4: =D4*30 -> 30000 | O4: =M4 -> 2000000 | P4: =D4*50 -> 50000 | Q4: =O4 -> 2000000
B5: =D5*0.5 -> 250 | C5: =E5 -> 666666.67 | D5: 500 | E5: 666666.67 | F5: =D5*2 -> 1000 | G5: =E5 -> 666666.67 | H5: =D5*5 -> 2500 | I5: =E5 -> 666666.67 | J5: =D5*10 -> 5000 | K5: =E5 -> 666666.67 | L5: =D5*20 -> 10000 | M5: =K5 -> 666666.67 | N5: =D5*30 -> 15000 | O5: =M5 -> 666666.67 | P5: =D5*50 -> 25000 | Q5: =O5 -> 666666.67
B6: =D6*0.5 -> 100 | C6: =E6 -> 400000 | D6: 200 | E6: 400000 | F6: =D6*2 -> 400 | G6: =E6 -> 400000 | H6: =D6*5 -> 1000 | I6: =E6 -> 400000 | J6: =D6*10 -> 2000 | K6: =E6 -> 400000 | L6: =D6*20 -> 4000 | M6: =K6 -> 400000 | N6: =D6*30 -> 6000 | O6: =M6 -> 400000 | P6: =D6*50 -> 10000 | Q6: =O6 -> 400000
B7: =D7*0.5 -> 70.95 | C7: =E7 -> 1000000 | D7: 141.9 | E7: 1000000 | F7: =D7*2 -> 283.8 | G7: =E7 -> 1000000 | H7: =D7*5 -> 709.5 | I7: =E7 -> 1000000 | J7: =D7*10 -> 1419 | K7: =E7 -> 1000000 | L7: =D7*20 -> 2838 | M7: =K7 -> 1000000 | N7: =D7*30 -> 4257 | O7: =M7 -> 1000000 | P7: =D7*50 -> 7095 | Q7: =O7 -> 1000000
B8: =D8*0.5 -> 62.5 | C8: =E8 -> 1000000 | D8: 125 | E8: 1000000 | F8: =D8*2 -> 250 | G8: =E8 -> 1000000 | H8: =D8*5 -> 625 | I8: =E8 -> 1000000 | J8: =D8*10 -> 1250 | K8: =E8 -> 1000000 | L8: =D8*20 -> 2500 | M8: =K8 -> 1000000 | N8: =D8*30 -> 3750 | O8: =M8 -> 1000000 | P8: =D8*50 -> 6250 | Q8: =O8 -> 1000000
B9: =D9*0.5 -> 57.5 | C9: =E9 -> 1000000 | D9: 115 | E9: 1000000 | F9: =D9*2 -> 230 | G9: =E9 -> 1000000 | H9: =D9*5 -> 575 | I9: =E9 -> 1000000 | J9: =D9*10 -> 1150 | K9: =E9 -> 1000000 | L9: =D9*20 -> 2300 | M9: =K9 -> 1000000 | N9: =D9*30 -> 3450 | O9: =M9 -> 1000000 | P9: =D9*50 -> 5750 | Q9: =O9 -> 1000000
B10: =D10*0.5 -> 50 | C10: =E10 -> 18018.018 | D10: 100 | E10: 18018.018 | F10: =D10*2 -> 200 | G10: =E10 -> 18018.018 | H10: =D10*5 -> 500 | I10: =E10 -> 18018.018 | J10: =D10*10 -> 1000 | K10: =E10 -> 18018.018 | L10: =D10*20 -> 2000 | M10: =K10 -> 18018.018 | N10: =D10*30 -> 3000 | O10: =M10 -> 18018.018 | P10: =D10*50 -> 5000 | Q10: =O10 -> 18018.018
B11: =D11*0.5 -> 45.95 | C11: =E11 -> 400000 | D11: 91.9 | E11: 400000 | F11: =D11*2 -> 183.8 | G11: =E11 -> 400000 | H11: =D11*5 -> 459.5 | I11: =E11 -> 400000 | J11: =D11*10 -> 919 | K11: =E11 -> 400000 | L11: =D11*20 -> 1838 | M11: =K11 -> 400000 | N11: =D11*30 -> 2757 | O11: =M11 -> 400000 | P11: =D11*50 -> 4595 | Q11: =O11 -> 400000
B12: =D12*0.5 -> 45 | C12: =E12 -> 1000000 | D12: 90 | E12: 1000000 | F12: =D12*2 -> 180 | G12: =E12 -> 1000000 | H12: =D12*5 -> 450 | I12: =E12 -> 1000000 | J12: =D12*10 -> 900 | K12: =E12 -> 1000000 | L12: =D12*20 -> 1800 | M12: =K12 -> 1000000 | N12: =D12*30 -> 2700 | O12: =M12 -> 1000000 | P12: =D12*50 -> 4500 | Q12: =O12 -> 1000000
B13: =D13*0.5 -> 43.95 | C13: =E13 -> 400000 | D13: 87.9 | E13: 400000 | F13: =D13*2 -> 175.8 | G13: =E13 -> 400000 | H13: =D13*5 -> 439.5 | I13: =E13 -> 400000 | J13: =D13*10 -> 879 | K13: =E13 -> 400000 | L13: =D13*20 -> 1758 | M13: =K13 -> 400000 | N13: =D13*30 -> 2637 | O13: =M13 -> 400000 | P13: =D13*50 -> 4395 | Q13: =O13 -> 400000
B14: =D14*0.5 -> 42.65 | C14: =E14 -> 333333.33 | D14: 85.3 | E14: 333333.33 | F14: =D14*2 -> 170.6 | G14: =E14 -> 333333.33 | H14: =D14*5 -> 426.5 | I14: =E14 -> 333333.33 | J14: =D14*10 -> 853 | K14: =E14 -> 333333.33 | L14: =D14*20 -> 1706 | M14: =K14 -> 333333.33 | N14: =D14*30 -> 2559 | O14: =M14 -> 333333.33 | P14: =D14*50 -> 4265 | Q14: =O14 -> 333333.33
B15: =D15*0.5 -> 42.5 | C15: =E15 -> 1000000 | D15: 85 | E15: 1000000 | F15: =D15*2 -> 170 | G15: =E15 -> 1000000 | H15: =D15*5 -> 425 | I15: =E15 -> 1000000 | J15: =D15*10 -> 850 | K15: =E15 -> 1000000 | L15: =D15*20 -> 1700 | M15: =K15 -> 1000000 | N15: =D15*30 -> 2550 | O15: =M15 -> 1000000 | P15: =D15*50 -> 4250 | Q15: =O15 -> 1000000
B16: =D16*0.5 -> 42.05 | C16: =E16 -> 200000 | D16: 84.1 | E16: 200000 | F16: =D16*2 -> 168.2 | G16: =E16 -> 200000 | H16: =D16*5 -> 420.5 | I16: =E16 -> 200000 | J16: =D16*10 -> 841 | K16: =E16 -> 200000 | L16: =D16*20 -> 1682 | M16: =K16 -> 200000 | N16: =D16*30 -> 2523 | O16: =M16 -> 200000 | P16: =D16*50 -> 4205 | Q16: =O16 -> 200000
... B197: =D197*0.5 -> 0.05 | C197: =E197 -> 28.571429 | D197: 0.1 | E197: 28.571429 | F197: =D197*2 -> 0.2 | G197: =E197 -> 28.571429 | H197: =D197*5 -> 0.5 | I197: =E197 -> 28.571429 | J197: =D197*10 -> 1 | K197: =E197 -> 28.571429 | L197: =D197*20 -> 2 | M197: =K197 -> 28.571429 | N197: =D197*30 -> 3 | O197: =M197 -> 28.571429 | P197: =D197*50 -> 5 | Q197: =O197 -> 28.571429
B198: NON WINNING | C198: =E198 -> 1.3638918 | D198: NON WINNING | E198: 1.3638918 | F198: NON WINNING | G198: =E198 -> 1.3638918 | H198: NON WINNING | I198: =E198 -> 1.3638918 | J198: NON WINNING | K198: =E198 -> 1.3638918 | L198: NON WINNING | M198: =K198 -> 1.3638918 | N198: NON WINNING | O198: =M198 -> 1.3638918 | P198: NON WINNING | Q198: =O198 -> 1.3638918

Sheet Summary(Delivery)
A1: Size of Grid | B1: 0.5 | C1: 1 | D1: 2 | E1: 5 | F1: 10 | G1: 20 | H1: 30 | I1: 50
A2: Top Prize | B2: =$C$2*B1 -> 500 | C2: 1000 | D2: =$C$2*D1 -> 2000 | E2: =$C$2*E1 -> 5000 | F2: =$C$2*F1 -> 10000 | G2: =$C$2*G1 -> 20000 | H2: =$C$2*H1 -> 30000 | I2: =$C$2*I1 -> 50000
A3: Version | B3: v1 | C3: v1 | D3: v1 | E3: v1 | F3: v1 | G3: v1 | H3: v1 | I3: v1
A4: Payout | B4: =C4 -> 0.83 | C4: 0.83 | D4: =C4 -> 0.83 | E4: =C4 -> 0.83 | F4: =C4 -> 0.83 | G4: =C4 -> 0.83 | H4: =C4 -> 0.83 | I4: =C4 -> 0.83
A5: Breakeven | B5: =C5 -> 0 | C5: 0 | D5: =C5 -> 0 | E5: =C5 -> 0 | F5: =C5 -> 0 | G5: =C5 -> 0 | H5: =C5 -> 0 | I5: =C5 -> 0
A6: Odds | B6: =C6 -> 3.7480697 | C6: 3.7480697 | D6: =C6 -> 3.7480697 | E6: =C6 -> 3.7480697 | F6: =C6 -> 3.7480697 | G6: =C6 -> 3.7480697 | H6: =C6 -> 3.7480697 | I6: =C6 -> 3.7480697
A7: Size of Grid | B7: 2000000 | C7: 2000000 | D7: 2000000 | E7: 2000000 | F7: 2000000 | G7: 2000000 | H7: 2000000 | I7: 2000000
A8: Low Tier Winning Range | B8: x0 - x5 | C8: x0 - x5 | D8: x0 - x5 | E8: x0 - x5 | F8: x0 - x5 | G8: x0 - x5 | H8: x0 - x5 | I8: x0 - x5
A9: Percentage in Low Tier | B9: =C9 -> 0.27972325 | C9: 0.27972325 | D9: =C9 -> 0.27972325 | E9: =C9 -> 0.27972325 | F9: =C9 -> 0.27972325 | G9: =C9 -> 0.27972325 | H9: =C9 -> 0.27972325 | I9: =C9 -> 0.27972325
A10: Medium Tier Winning Range | B10: x5 - x20 | C10: x5 - x20 | D10: x5 - x20 | E10: x5 - x20 | F10: x5 - x20 | G10: x5 - x20 | H10: x5 - x20 | I10: x5 - x20
A11: Percentage in Medium Tier | B11: =C11 -> 0.27419319 | C11: 0.27419319 | D11: =C11 -> 0.27419319 | E11: =C11 -> 0.27419319 | F11: =C11 -> 0.27419319 | G11: =C11 -> 0.27419319 | H11: =C11 -> 0.27419319 | I11: =C11 -> 0.27419319
A12: High Tier Winning Range | B12: x20 - top | C12: x20 - top | D12: x20 - top | E12: x20 - top | F12: x20 - top | G12: x20 - top | H12: x20 - top | I12: x20 - top
A13: Percentage in High Tier | B13: =C13 -> 0.44608355 | C13: 0.44608355 | D13: =C13 -> 0.44608355 | E13: =C13 -> 0.44608355 | F13: =C13 -> 0.44608355 | G13: =C13 -> 0.44608355 | H13: =C13 -> 0.44608355 | I13: =C13 -> 0.44608355
A14: Total Pool Amount | B14: =B7*B4*B1 -> 830000 | C14: =C7*C4*C1 -> 1660000 | D14: =D7*D4*D1 -> 3320000 | E14: =E7*E4*E1 -> 8300000 | F14: =F7*F4*F1 -> 16600000 | G14: =G7*G4*G1 -> 33200000 | H14: =H7*H4*H1 -> 49800000 | I14: =I7*I4*I1 -> 83000000
A15: Progressive Jackpot Info | B15: 0.5 | C15: 1 | D15: 2 | E15: 5 | F15: 10 | G15: 20 | H15: 30 | I15: 50
A16: Size of Grid | B16: 50000000 | C16: 50000000 | D16: 50000000 | E16: 50000000 | F16: 50000000 | G16: 50000000 | H16: 50000000 | I16: 50000000
A17: JP2 Wins/Grid | B17: =$C$17*B15 -> 0.5 | C17: 1 | D17: =$C$17*D15 -> 2 | E17: =$C$17*E15 -> 5 | F17: =$C$17*F15 -> 10 | G17: =$C$17*G15 -> 20 | H17: =$C$17*H15 -> 30 | I17: =$C$17*I15 -> 50
A18: JP1 Wins/Grid | B18: =$C$18*B15 -> 20 | C18: 40 | D18: =$C$18*D15 -> 80 | E18: =$C$18*E15 -> 200 | F18: =$C$18*F15 -> 400 | G18: =$C$18*G15 -> 800 | H18: =$C$18*H15 -> 1200 | I18: =$C$18*I15 -> 2000
A19: JP2 Wins/Price Ratio | B19: =C19 -> 1 | C19: 1 | D19: =C19 -> 1 | E19: =C19 -> 1 | F19: =C19 -> 1 | G19: =C19 -> 1 | H19: =C19 -> 1 | I19: =C19 -> 1
A20: JP1 Wins/Price Ratio | B20: =C20 -> 40 | C20: 40 | D20: =C20 -> 40 | E20: =C20 -> 40 | F20: =C20 -> 40 | G20: =C20 -> 40 | H20: =C20 -> 40 | I20: =C20 -> 40
A21: Odds of JP1 Win | B21: =$C$21/B15 -> 2500000 | C21: 1250000 | D21: =$C$21/D15 -> 625000 | E21: =$C$21/E15 -> 250000 | F21: =$C$21/F15 -> 125000 | G21: =$C$21/G15 -> 62500 | H21: =$C$21/H15 -> 41666.667 | I21: =$C$21/I15 -> 25000
A22: Odds of JP2 Win | B22: =$C$22/B15 -> 100000000 | C22: 50000000 | D22: =$C$22/D15 -> 25000000 | E22: =$C$22/E15 -> 10000000 | F22: =$C$22/F15 -> 5000000 | G22: =$C$22/G15 -> 2500000 | H22: =$C$22/H15 -> 1666666.7 | I22: =$C$22/I15 -> 1000000
A23: Revenue/JP win | B23: =B16*B15 -> 25000000 | C23: =C16*C15 -> 50000000 | D23: =D16*D15 -> 100000000 | E23: =E16*E15 -> 250000000 | F23: =F16*F15 -> 500000000 | G23: =G16*G15 -> 1000000000 | H23: =H16*H15 -> 1500000000 | I23: =I16*I15 -> 2500000000
A24: Jackpot Reset % | B24: =C24 -> 0.005 | C24: 0.005 | D24: =C24 -> 0.005 | E24: =C24 -> 0.005 | F24: =C24 -> 0.005 | G24: =C24 -> 0.005 | H24: =C24 -> 0.005 | I24: =C24 -> 0.005
A25: JP1 Reset Value | B25: 2500 | C25: 2500 | D25: 2500 | E25: 2500 | F25: 2500 | G25: 2500 | H25: 2500 | I25: 2500
A26: JP2 Reset Value | B26: 150000 | C26: 150000 | D26: 150000 | E26: 150000 | F26: 150000 | G26: 150000 | H26: 150000 | I26: 150000
A27: Jackpot Increment % | B27: =C27 -> 0.035 | C27: 0.035 | D27: =C27 -> 0.035 | E27: =C27 -> 0.035 | F27: =C27 -> 0.035 | G27: =C27 -> 0.035 | H27: =C27 -> 0.035 | I27: =C27 -> 0.035
A28: Jackpot Increment Amount | B28: =$C$28*B15 -> 0.0175 | C28: =C27*C17 -> 0.035 | D28: =$C$28*D15 -> 0.07 | E28: =$C$28*E15 -> 0.175 | F28: =$C$28*F15 -> 0.35 | G28: =$C$28*G15 -> 0.7 | H28: =$C$28*H15 -> 1.05 | I28: =$C$28*I15 -> 1.75

Sheet Prize Breakdown
B2: Tier | C2: Win Methods | D2: Prize | E2: Symbol | F2: Quantity of Symbols
B3: 1 | C3: main-0 | D3: 0.1 | E3: A/B/C/D | F3: 3
B4: 2 | C4: main-1 | D4: 0.2 | E4: A/B/C/D | F4: 4
B5: 3 | C5: main-2 | D5: 0.5 | E5: A/B/C/D | F5: 5
B6: 4 | C6: main-3 | D6: 1 | E6: A/B/C/D | F6: 6
B7: 5 | C7: main-4 | D7: 1.5 | E7: A/B/C/D | F7: 7
B8: 6 | C8: main-5 | D8: 2 | E8: A/B/C/D | F8: 8 | H8: Quantity of Symbols | I8: A | J8: B | K8: C | L8: D | M8: E | N8: F | O8: G
B9: 7 | C9: main-6 | D9: 2.5 | E9: A/B/C/D | F9: 9 | H9: 3 | I9: 0.1 | J9: 0.1 | K9: 0.1 | L9: 0.1 | M9: 1 | N9: 1.5 | O9: 2
B10: 8 | C10: main-7 | D10: 3 | E10: A/B/C/D | F10: 10 | H10: 4 | I10: 0.2 | J10: 0.2 | K10: 0.2 | L10: 0.2 | M10: 1.5 | N10: 2 | O10: 5
B11: 9 | C11: main-8 | D11: 5 | E11: A/B/C/D | F11: 11 | H11: 5 | I11: 0.5 | J11: 0.5 | K11: 0.5 | L11: 0.5 | M11: 2 | N11: 5 | O11: 10
B12: 10 | C12: main-9 | D12: 10 | E12: A | F12: 12 | H12: 6 | I12: 1 | J12: 1 | K12: 1 | L12: 1 | M12: 5 | N12: 10 | O12: 15
B13: 11 | C13: main-10 | D13: 1 | E13: E | F13: 3 | H13: 7 | I13: 1.5 | J13: 1.5 | K13: 1.5 | L13: 1.5 | M13: 10 | N13: 15 | O13: 20
B14: 12 | C14: main-11 | D14: 1.5 | E14: E | F14: 4 | H14: 8 | I14: 2 | J14: 2 | K14: 2 | L14: 2 | M14: 15 | N14: 20 | O14: 50
B15: 13 | C15: main-12 | D15: 2 | E15: E | F15: 5 | H15: 9 | I15: 2.5 | J15: 2.5 | K15: 2.5 | L15: 2.5 | M15: 20 | N15: 50 | O15: 100
B16: 14 | C16: main-13 | D16: 5 | E16: E | F16: 6 | H16: 10 | I16: 3 | J16: 3 | K16: 3 | L16: 3 | M16: 50 | N16: 100 | O16: 200
B17: 15 | C17: main-14 | D17: 10 | E17: E | F17: 7 | H17: 11 | I17: 5 | J17: 5 | K17: 5 | L17: 5 | M17: 100 | N17: 200 | O17: 500
B18: 16 | C18: main-15 | D18: 15 | E18: E | F18: 8 | H18: 12 | I18: 10 | J18: 15 | K18: 20 | L18: 30 | M18: 200 | N18: 500 | O18: 1000 | P18: -
B19: 17 | C19: main-16 | D19: 20 | E19: E | F19: 9
B20: 18 | C20: main-17 | D20: 50 | E20: E | F20: 10
B21: 19 | C21: main-18 | D21: 100 | E21: E | F21: 11
B22: 20 | C22: main-19 | D22: 200 | E22: E | F22: 12
B23: 21 | C23: main-20 | D23: 1.5 | E23: F | F23: 3
B24: 22 | C24: main-21 | D24: 2 | E24: F | F24: 4
B25: 23 | C25: main-22 | D25: 5 | E25: F | F25: 5
B26: 24 | C26: main-23 | D26: 10 | E26: F | F26: 6
B27: 25 | C27: main-24 | D27: 15 | E27: F | F27: 7
B28: 26 | C28: main-25 | D28: 20 | E28: F | F28: 8
B29: 27 | C29: main-26 | D29: 50 | E29: F | F29: 9
B30: 28 | C30: main-27 | D30: 100 | E30: F | F30: 10
... B83: 354 | C83: bonusA-6 | D83: 100 | E83: Super Spin Jackpot | F83: 3

Sheet Summary
B3: Odds Down (ticket quantity if pool based): | C3: =Frequency!N6 -> 2000000
B4: Base(ticket price): | C4: =Frequency!N7 -> 1
B5: Revenue (if pool based): | C5: =C3*C4 -> 2000000
B6: Base Prize fund (if pool based): | C6: =C5*C8 -> 1660000
B7: Max prize | C7: =MAX(Tiers!C3:C4874) -> 1000
B8: Base RTP setting(JP exclude) | C8: =Frequency!N10 -> 0.83
B9: Hit Rate | C9: =Summary!C3/(C3-Frequency!E4) -> 3.7480697
B10: Std. Dev. | C10: =('Data Analysis'!BO357/Summary!C3)^0.5 -> 4.2248542
B12: Freeplay Overall Freq | C12: =C3/('Data Analysis'!AV357+'Data Analysis'!AX357+'Data Analysis'!AZ357+'Data Analysis'!BB357) -> 195.35065 | E12: 20x Multi Freq | F12: =C3/'Data Analysis'!G357 -> 65.299726
B13: Freeplay Overall Avg. Multi | C13: =('Data Analysis'!BC357+'Data Analysis'!BA357+'Data Analysis'!AY357+'Data Analysis'!AW357)/('Data Analysis'!BB357+'Data Analysis'!AZ357+'Data Analysis'!AX357+'Data Analysis'!AV357) -> 28.147392 | E13: 20x Multi Avg. Payout | F13: ='Data Analysis'!H357/'Data Analysis'!G357 -> 17.957973
B14: Freeplay Overall Value Share | C14: =('Data Analysis'!BC357+'Data Analysis'!BA357+'Data Analysis'!AY357+'Data Analysis'!AW357)/C6 -> 0.17359819 | E14: Multi Value Share | F14: ='Data Analysis'!H357/Summary!C6 -> 0.33133542
B15: freeplayA Freq | C15: =Summary!C3/'Data Analysis'!AV357 -> 195.35065
B16: freeplayA Avg. Multi | C16: ='Data Analysis'!AW357/'Data Analysis'!AV357 -> 28.147392
B17: freeplayA Value Share | C17: ='Data Analysis'!AW357/Summary!C6 -> 0.17359819
B19: Bonus Overall Freq | C19: =C3/('Data Analysis'!BH357+'Data Analysis'!BF357+'Data Analysis'!BD357) -> 84.530854 | D19: SSJ
B20: Bonus Overall Multi | C20: =('Data Analysis'!BI357+'Data Analysis'!BG357+'Data Analysis'!BE357)/('Data Analysis'!BH357+'Data Analysis'!BF357+'Data Analysis'!BD357) -> 23.421188
B21: Bonus Overall Value Share | C21: =('Data Analysis'!BI357+'Data Analysis'!BG357+'Data Analysis'!BE357)/C6 -> 0.33382247
B22: bonusA Freq | C22: =C3/'Data Analysis'!BD357 -> 84.530854
B23: bonusA Multi | C23: ='Data Analysis'!BE357/'Data Analysis'!BD357 -> 23.421188
B24: bonusA Value Share | C24: ='Data Analysis'!BE357/Summary!C6 -> 0.33382247
B26: Feature(Bonus + Freeplay) Freq | C26: =C3/('Data Analysis'!BH357+'Data Analysis'!BF357+'Data Analysis'!BD357+'Data Analysis'!BB357+'Data Analysis'!AZ357+'Data Analysis'!AX357+'Data Analysis'!AV357) -> 59.000531
B27: Feature Overall Multi | C27: =('Data Analysis'!AW357+'Data Analysis'!AY357+'Data Analysis'!BA357+'Data Analysis'!BC357+'Data Analysis'!BE357+'Data Analysis'!BG357+'Data Analysis'!BI357)/('Data Analysis'!BH357+'Data Analysis'!BF357+'Data Analysis'!BD357+'Data Analysis'!BB357+'Data Analysis'!AZ357+'Data Analysis'!AX357+'Data Analysis'!AV357) -> 24.848613
B28: Feature Overall Value Share | C28: =('Data Analysis'!AW357+'Data Analysis'!AY357+'Data Analysis'!BA357+'Data Analysis'!BC357+'Data Analysis'!BE357+'Data Analysis'!BG357+'Data Analysis'!BI357)/C6 -> 0.50742066
B31: Combo Win Freq | C31: =C3/'Data Analysis'!AK357 -> 20.894275
B32: Combo Win Multi | C32: ='Data Analysis'!AL357/'Data Analysis'!AK357 -> 7.6216977
B34: Category | C34: Freq | D34: Prob. | E34: Odds Dist. | F34: Value Dist. | G34: Hit Dist.
B35: NIL | C35: ='Data Analysis'!E2 -> 1466392 | D35: =C35/$C$46 -> 0.733196 | E35: =1/D35 -> 1.3638918 | F35: - | G35: -
B36: >0 to <1 | C36: ='Data Analysis'!M357 -> 190004 | D36: =C36/$C$46 -> 0.095002 | E36: =1/D36 -> 10.526094 | F36: ='Data Analysis'!N357/Summary!C6 -> 0.026627169 | G36: =C36/SUM($C$36:$C$45) -> 0.35607412
B37: =1 -> 1 | C37: ='Data Analysis'!O357 -> 133806 | D37: =C37/$C$46 -> 0.066903 | E37: =1/D37 -> 14.947013 | F37: ='Data Analysis'!P357/Summary!C6 -> 0.080606024 | G37: =C37/SUM($C$36:$C$45) -> 0.25075711
B38: >1 to 2 | C38: ='Data Analysis'!Q357 -> 142772 | D38: =C38/$C$46 -> 0.071386 | E38: =1/D38 -> 14.008349 | F38: ='Data Analysis'!R357/Summary!C6 -> 0.14475542 | G38: =C38/SUM($C$36:$C$45) -> 0.26755971
B39: >2 to 5 | C39: ='Data Analysis'!S357 -> 11912 | D39: =C39/$C$46 -> 0.005956 | E39: =1/D39 -> 167.89792 | F39: ='Data Analysis'!T357/Summary!C6 -> 0.027734639 | G39: =C39/SUM($C$36:$C$45) -> 0.022323503 | H39: =F36+F37+F38+F39 -> 0.27972325
B40: >5 to 10 | C40: ='Data Analysis'!U357 -> 10924 | D40: =C40/$C$46 -> 0.005462 | E40: =1/D40 -> 183.08312 | F40: ='Data Analysis'!V357/Summary!C6 -> 0.058778554 | G40: =C40/SUM($C$36:$C$45) -> 0.020471957 | H40: =F40+F41 -> 0.27419319
B41: >10 to 20 | C41: ='Data Analysis'!W357 -> 21594 | D41: =C41/$C$46 -> 0.010797 | E41: =1/D41 -> 92.61832 | F41: ='Data Analysis'!X357/Summary!C6 -> 0.21541464 | G41: =C41/SUM($C$36:$C$45) -> 0.040467909 | H41: =F42+F43+F44+F45 -> 0.44608355
B42: >20 to 30 | C42: ='Data Analysis'!Y357 -> 13920 | D42: =C42/$C$46 -> 0.00696 | E42: =1/D42 -> 143.67816 | F42: ='Data Analysis'!Z357/Summary!C6 -> 0.21372693 | G42: =C42/SUM($C$36:$C$45) -> 0.026086565
B43: >30 to 50 | C43: ='Data Analysis'!AA357 -> 6916 | D43: =C43/$C$46 -> 0.003458 | E43: =1/D43 -> 289.1845 | F43: ='Data Analysis'!AB357/Summary!C6 -> 0.1636903 | G43: =C43/SUM($C$36:$C$45) -> 0.012960825
B44: >50 to 100 | C44: ='Data Analysis'!AC357 -> 1745 | D44: =C44/$C$46 -> 0.0008725 | E44: =1/D44 -> 1146.1318 | F44: ='Data Analysis'!AD357/Summary!C6 -> 0.066097771 | G44: =C44/SUM($C$36:$C$45) -> 0.0032701909
B45: >100 | C45: ='Data Analysis'!AE357 -> 15 | D45: =C45/$C$46 -> 7.5e-06 | E45: =1/D45 -> 133333.33 | F45: ='Data Analysis'!AF357/Summary!C6 -> 0.0025685542 | G45: =C45/SUM($C$36:$C$45) -> 2.8110523e-05
C46: =SUM(C35:C45) -> 2000000 | F46: =SUM(F36:F45) -> 1 | G46: =SUM(G36:G45) -> 1

Sheet Tiers
B2: Tier | C2: Total Prize | D2: Multiplier | E2: Method 1 | F2: Prize 1 | G2: Method 2 | H2: Prize 2 | I2: Method 3 | J2: Prize 3 | K2: Method 4 | L2: Prize 4 | M2: Method 5 | N2: Prize 5 | O2: Method 6 | P2: Prize 6 | Q2: Method 7 | R2: Prize 7 | S2: Method 8 | T2: Prize 8 | U2: Method 9 | V2: Prize 9 | W2: Method 10 | X2: Prize 10 | Y2: Method
B3: 0 | C3: =(F3+H3+J3+L3+N3+P3+R3+T3+V3+X3)*D3 -> 0 | D3: 1 | F3: =VLOOKUP(E3,'Win Methods'!$C$4:$F$4992,4,FALSE) -> 0 | H3: =VLOOKUP(G3,'Win Methods'!$C$4:$F$4992,4,FALSE) -> 0 | J3: =VLOOKUP(I3,'Win Methods'!$C$4:$F$4992,4,FALSE) -> 0 | L3: =VLOOKUP(K3,'Win Methods'!$C$4:$F$4992,4,FALSE) -> 0 | N3: =VLOOKUP(M3,'Win Methods'!$C$4:$F$4992,4,FALSE) -> 0 | P3: =VLOOKUP(O3,'Win Methods'!$C$4:$F$4992,4,FALSE) -> 0 | R3: =VLOOKUP(Q3,'Win Methods'!$C$4:$F$4992,4,FALSE) -> 0 | T3: =VLOOKUP(S3,'Win Methods'!$C$4:$F$4992,4,FALSE) -> 0 | V3: =VLOOKUP(U3,'Win Methods'!$C$4:$F$4992,4,FALSE) -> 0 | X3: =VLOOKUP(W3,'Win Methods'!$C$4:$F$4992,4,FALSE) -> 0 | Y3: =E3&"|"&G3&"|"&I3&"|"&K3&"|"&M3&"|"&O3&"|"&Q3&"|"&S3&"|"&U3&"|"&W3 &" x "&D3 -> ||||||||| x 1
B4: 1 | C4: =(F4+H4+J4+L4+N4+P4+R4+T4+V4+X4)*D4 -> 0.1 | D4: 1 | E4: main-0 | F4: =VLOOKUP(E4,'Win Methods'!$C$4:$F$4992,4,FALSE) -> 0.1 | H4: =VLOOKUP(G4,'Win Methods'!$C$4:$F$4992,4,FALSE) -> 0 | J4: =VLOOKUP(I4,'Win Methods'!$C$4:$F$4992,4,FALSE) -> 0 | L4: =VLOOKUP(K4,'Win Methods'!$C$4:$F$4992,4,FALSE) -> 0 | N4: =VLOOKUP(M4,'Win Methods'!$C$4:$F$4992,4,FALSE) -> 0 | P4: =VLOOKUP(O4,'Win Methods'!$C$4:$F$4992,4,FALSE) -> 0 | R4: =VLOOKUP(Q4,'Win Methods'!$C$4:$F$4992,4,FALSE) -> 0 | T4: =VLOOKUP(S4,'Win Methods'!$C$4:$F$4992,4,FALSE) -> 0 | V4: =VLOOKUP(U4,'Win Methods'!$C$4:$F$4992,4,FALSE) -> 0 | X4: =VLOOKUP(W4,'Win Methods'!$C$4:$F$4992,4,FALSE) -> 0 | Y4: =E4&"|"&G4&"|"&I4&"|"&K4&"|"&M4&"|"&O4&"|"&Q4&"|"&S4&"|"&U4&"|"&W4 &" x "&D4 -> main-0||||||||| x 1
B5: 2 | C5: =(F5+H5+J5+L5+N5+P5+R5+T5+V5+X5)*D5 -> 0.2 | D5: 1 | E5: main-1 | F5: =VLOOKUP(E5,'Win Methods'!$C$4:$F$4992,4,FALSE) -> 0.2 | H5: =VLOOKUP(G5,'Win Methods'!$C$4:$F$4992,4,FALSE) -> 0 | J5: =VLOOKUP(I5,'Win Methods'!$C$4:$F$4992,4,FALSE) -> 0 | L5: =VLOOKUP(K5,'Win Methods'!$C$4:$F$4992,4,FALSE) -> 0 | N5: =VLOOKUP(M5,'Win Methods'!$C$4:$F$4992,4,FALSE) -> 0 | P5: =VLOOKUP(O5,'Win Methods'!$C$4:$F$4992,4,FALSE) -> 0 | R5: =VLOOKUP(Q5,'Win Methods'!$C$4:$F$4992,4,FALSE) -> 0 | T5: =VLOOKUP(S5,'Win Methods'!$C$4:$F$4992,4,FALSE) -> 0 | V5: =VLOOKUP(U5,'Win Methods'!$C$4:$F$4992,4,FALSE) -> 0 | X5: =VLOOKUP(W5,'Win Methods'!$C$4:$F$4992,4,FALSE) -> 0 | Y5: =E5&"|"&G5&"|"&I5&"|"&K5&"|"&M5&"|"&O5&"|"&Q5&"|"&S5&"|"&U5&"|"&W5 &" x "&D5 -> main-1||||||||| x 1
B6: 3 | C6: =(F6+H6+J6+L6+N6+P6+R6+T6+V6+X6)*D6 -> 0.5 | D6: 1 | E6: main-2 | F6: =VLOOKUP(E6,'Win Methods'!$C$4:$F$4992,4,FALSE) -> 0.5 | H6: =VLOOKUP(G6,'Win Methods'!$C$4:$F$4992,4,FALSE) -> 0 | J6: =VLOOKUP(I6,'Win Methods'!$C$4:$F$4992,4,FALSE) -> 0 | L6: =VLOOKUP(K6,'Win Methods'!$C$4:$F$4992,4,FALSE) -> 0 | N6: =VLOOKUP(M6,'Win Methods'!$C$4:$F$4992,4,FALSE) -> 0 | P6: =VLOOKUP(O6,'Win Methods'!$C$4:$F$4992,4,FALSE) -> 0 | R6: =VLOOKUP(Q6,'Win Methods'!$C$4:$F$4992,4,FALSE) -> 0 | T6: =VLOOKUP(S6,'Win Methods'!$C$4:$F$4992,4,FALSE) -> 0 | V6: =VLOOKUP(U6,'Win Methods'!$C$4:$F$4992,4,FALSE) -> 0 | X6: =VLOOKUP(W6,'Win Methods'!$C$4:$F$4992,4,FALSE) -> 0 | Y6: =E6&"|"&G6&"|"&I6&"|"&K6&"|"&M6&"|"&O6&"|"&Q6&"|"&S6&"|"&U6&"|"&W6 &" x "&D6 -> main-2||||||||| x 1
B7: 4 | C7: =(F7+H7+J7+L7+N7+P7+R7+T7+V7+X7)*D7 -> 1 | D7: 1 | E7: main-3 | F7: =VLOOKUP(E7,'Win Methods'!$C$4:$F$4992,4,FALSE) -> 1 | H7: =VLOOKUP(G7,'Win Methods'!$C$4:$F$4992,4,FALSE) -> 0 | J7: =VLOOKUP(I7,'Win Methods'!$C$4:$F$4992,4,FALSE) -> 0 | L7: =VLOOKUP(K7,'Win Methods'!$C$4:$F$4992,4,FALSE) -> 0 | N7: =VLOOKUP(M7,'Win Methods'!$C$4:$F$4992,4,FALSE) -> 0 | P7: =VLOOKUP(O7,'Win Methods'!$C$4:$F$4992,4,FALSE) -> 0 | R7: =VLOOKUP(Q7,'Win Methods'!$C$4:$F$4992,4,FALSE) -> 0 | T7: =VLOOKUP(S7,'Win Methods'!$C$4:$F$4992,4,FALSE) -> 0 | V7: =VLOOKUP(U7,'Win Methods'!$C$4:$F$4992,4,FALSE) -> 0 | X7: =VLOOKUP(W7,'Win Methods'!$C$4:$F$4992,4,FALSE) -> 0 | Y7: =E7&"|"&G7&"|"&I7&"|"&K7&"|"&M7&"|"&O7&"|"&Q7&"|"&S7&"|"&U7&"|"&W7 &" x "&D7 -> main-3||||||||| x 1
B8: 5 | C8: =(F8+H8+J8+L8+N8+P8+R8+T8+V8+X8)*D8 -> 1.5 | D8: 1 | E8: main-4 | F8: =VLOOKUP(E8,'Win Methods'!$C$4:$F$4992,4,FALSE) -> 1.5 | H8: =VLOOKUP(G8,'Win Methods'!$C$4:$F$4992,4,FALSE) -> 0 | J8: =VLOOKUP(I8,'Win Methods'!$C$4:$F$4992,4,FALSE) -> 0 | L8: =VLOOKUP(K8,'Win Methods'!$C$4:$F$4992,4,FALSE) -> 0 | N8: =VLOOKUP(M8,'Win Methods'!$C$4:$F$4992,4,FALSE) -> 0 | P8: =VLOOKUP(O8,'Win Methods'!$C$4:$F$4992,4,FALSE) -> 0 | R8: =VLOOKUP(Q8,'Win Methods'!$C$4:$F$4992,4,FALSE) -> 0 | T8: =VLOOKUP(S8,'Win Methods'!$C$4:$F$4992,4,FALSE) -> 0 | V8: =VLOOKUP(U8,'Win Methods'!$C$4:$F$4992,4,FALSE) -> 0 | X8: =VLOOKUP(W8,'Win Methods'!$C$4:$F$4992,4,FALSE) -> 0 | Y8: =E8&"|"&G8&"|"&I8&"|"&K8&"|"&M8&"|"&O8&"|"&Q8&"|"&S8&"|"&U8&"|"&W8 &" x "&D8 -> main-4||||||||| x 1
B9: 6 | C9: =(F9+H9+J9+L9+N9+P9+R9+T9+V9+X9)*D9 -> 2 | D9: 1 | E9: main-5 | F9: =VLOOKUP(E9,'Win Methods'!$C$4:$F$4992,4,FALSE) -> 2 | H9: =VLOOKUP(G9,'Win Methods'!$C$4:$F$4992,4,FALSE) -> 0 | J9: =VLOOKUP(I9,'Win Methods'!$C$4:$F$4992,4,FALSE) -> 0 | L9: =VLOOKUP(K9,'Win Methods'!$C$4:$F$4992,4,FALSE) -> 0 | N9: =VLOOKUP(M9,'Win Methods'!$C$4:$F$4992,4,FALSE) -> 0 | P9: =VLOOKUP(O9,'Win Methods'!$C$4:$F$4992,4,FALSE) -> 0 | R9: =VLOOKUP(Q9,'Win Methods'!$C$4:$F$4992,4,FALSE) -> 0 | T9: =VLOOKUP(S9,'Win Methods'!$C$4:$F$4992,4,FALSE) -> 0 | V9: =VLOOKUP(U9,'Win Methods'!$C$4:$F$4992,4,FALSE) -> 0 | X9: =VLOOKUP(W9,'Win Methods'!$C$4:$F$4992,4,FALSE) -> 0 | Y9: =E9&"|"&G9&"|"&I9&"|"&K9&"|"&M9&"|"&O9&"|"&Q9&"|"&S9&"|"&U9&"|"&W9 &" x "&D9 -> main-5||||||||| x 1
B10: 7 | C10: =(F10+H10+J10+L10+N10+P10+R10+T10+V10+X10)*D10 -> 2.5 | D10: 1 | E10: main-6 | F10: =VLOOKUP(E10,'Win Methods'!$C$4:$F$4992,4,FALSE) -> 2.5 | H10: =VLOOKUP(G10,'Win Methods'!$C$4:$F$4992,4,FALSE) -> 0 | J10: =VLOOKUP(I10,'Win Methods'!$C$4:$F$4992,4,FALSE) -> 0 | L10: =VLOOKUP(K10,'Win Methods'!$C$4:$F$4992,4,FALSE) -> 0 | N10: =VLOOKUP(M10,'Win Methods'!$C$4:$F$4992,4,FALSE) -> 0 | P10: =VLOOKUP(O10,'Win Methods'!$C$4:$F$4992,4,FALSE) -> 0 | R10: =VLOOKUP(Q10,'Win Methods'!$C$4:$F$4992,4,FALSE) -> 0 | T10: =VLOOKUP(S10,'Win Methods'!$C$4:$F$4992,4,FALSE) -> 0 | V10: =VLOOKUP(U10,'Win Methods'!$C$4:$F$4992,4,FALSE) -> 0 | X10: =VLOOKUP(W10,'Win Methods'!$C$4:$F$4992,4,FALSE) -> 0 | Y10: =E10&"|"&G10&"|"&I10&"|"&K10&"|"&M10&"|"&O10&"|"&Q10&"|"&S10&"|"&U10&"|"&W10 &" x "&D10 -> main-6||||||||| x 1
B11: 8 | C11: =(F11+H11+J11+L11+N11+P11+R11+T11+V11+X11)*D11 -> 3 | D11: 1 | E11: main-7 | F11: =VLOOKUP(E11,'Win Methods'!$C$4:$F$4992,4,FALSE) -> 3 | H11: =VLOOKUP(G11,'Win Methods'!$C$4:$F$4992,4,FALSE) -> 0 | J11: =VLOOKUP(I11,'Win Methods'!$C$4:$F$4992,4,FALSE) -> 0 | L11: =VLOOKUP(K11,'Win Methods'!$C$4:$F$4992,4,FALSE) -> 0 | N11: =VLOOKUP(M11,'Win Methods'!$C$4:$F$4992,4,FALSE) -> 0 | P11: =VLOOKUP(O11,'Win Methods'!$C$4:$F$4992,4,FALSE) -> 0 | R11: =VLOOKUP(Q11,'Win Methods'!$C$4:$F$4992,4,FALSE) -> 0 | T11: =VLOOKUP(S11,'Win Methods'!$C$4:$F$4992,4,FALSE) -> 0 | V11: =VLOOKUP(U11,'Win Methods'!$C$4:$F$4992,4,FALSE) -> 0 | X11: =VLOOKUP(W11,'Win Methods'!$C$4:$F$4992,4,FALSE) -> 0 | Y11: =E11&"|"&G11&"|"&I11&"|"&K11&"|"&M11&"|"&O11&"|"&Q11&"|"&S11&"|"&U11&"|"&W11 &" x "&D11 -> main-7||||||||| x 1
B12: 9 | C12: =(F12+H12+J12+L12+N12+P12+R12+T12+V12+X12)*D12 -> 5 | D12: 1 | E12: main-8 | F12: =VLOOKUP(E12,'Win Methods'!$C$4:$F$4992,4,FALSE) -> 5 | H12: =VLOOKUP(G12,'Win Methods'!$C$4:$F$4992,4,FALSE) -> 0 | J12: =VLOOKUP(I12,'Win Methods'!$C$4:$F$4992,4,FALSE) -> 0 | L12: =VLOOKUP(K12,'Win Methods'!$C$4:$F$4992,4,FALSE) -> 0 | N12: =VLOOKUP(M12,'Win Methods'!$C$4:$F$4992,4,FALSE) -> 0 | P12: =VLOOKUP(O12,'Win Methods'!$C$4:$F$4992,4,FALSE) -> 0 | R12: =VLOOKUP(Q12,'Win Methods'!$C$4:$F$4992,4,FALSE) -> 0 | T12: =VLOOKUP(S12,'Win Methods'!$C$4:$F$4992,4,FALSE) -> 0 | V12: =VLOOKUP(U12,'Win Methods'!$C$4:$F$4992,4,FALSE) -> 0 | X12: =VLOOKUP(W12,'Win Methods'!$C$4:$F$4992,4,FALSE) -> 0 | Y12: =E12&"|"&G12&"|"&I12&"|"&K12&"|"&M12&"|"&O12&"|"&Q12&"|"&S12&"|"&U12&"|"&W12 &" x "&D12 -> main-8||||||||| x 1
B13: 10 | C13: =(F13+H13+J13+L13+N13+P13+R13+T13+V13+X13)*D13 -> 10 | D13: 1 | E13: main-9 | F13: =VLOOKUP(E13,'Win Methods'!$C$4:$F$4992,4,FALSE) -> 10 | H13: =VLOOKUP(G13,'Win Methods'!$C$4:$F$4992,4,FALSE) -> 0 | J13: =VLOOKUP(I13,'Win Methods'!$C$4:$F$4992,4,FALSE) -> 0 | L13: =VLOOKUP(K13,'Win Methods'!$C$4:$F$4992,4,FALSE) -> 0 | N13: =VLOOKUP(M13,'Win Methods'!$C$4:$F$4992,4,FALSE) -> 0 | P13: =VLOOKUP(O13,'Win Methods'!$C$4:$F$4992,4,FALSE) -> 0 | R13: =VLOOKUP(Q13,'Win Methods'!$C$4:$F$4992,4,FALSE) -> 0 | T13: =VLOOKUP(S13,'Win Methods'!$C$4:$F$4992,4,FALSE) -> 0 | V13: =VLOOKUP(U13,'Win Methods'!$C$4:$F$4992,4,FALSE) -> 0 | X13: =VLOOKUP(W13,'Win Methods'!$C$4:$F$4992,4,FALSE) -> 0 | Y13: =E13&"|"&G13&"|"&I13&"|"&K13&"|"&M13&"|"&O13&"|"&Q13&"|"&S13&"|"&U13&"|"&W13 &" x "&D13 -> main-9||||||||| x 1
B14: 11 | C14: =(F14+H14+J14+L14+N14+P14+R14+T14+V14+X14)*D14 -> 1 | D14: 1 | E14: main-10 | F14: =VLOOKUP(E14,'Win Methods'!$C$4:$F$4992,4,FALSE) -> 1 | H14: =VLOOKUP(G14,'Win Methods'!$C$4:$F$4992,4,FALSE) -> 0 | J14: =VLOOKUP(I14,'Win Methods'!$C$4:$F$4992,4,FALSE) -> 0 | L14: =VLOOKUP(K14,'Win Methods'!$C$4:$F$4992,4,FALSE) -> 0 | N14: =VLOOKUP(M14,'Win Methods'!$C$4:$F$4992,4,FALSE) -> 0 | P14: =VLOOKUP(O14,'Win Methods'!$C$4:$F$4992,4,FALSE) -> 0 | R14: =VLOOKUP(Q14,'Win Methods'!$C$4:$F$4992,4,FALSE) -> 0 | T14: =VLOOKUP(S14,'Win Methods'!$C$4:$F$4992,4,FALSE) -> 0 | V14: =VLOOKUP(U14,'Win Methods'!$C$4:$F$4992,4,FALSE) -> 0 | X14: =VLOOKUP(W14,'Win Methods'!$C$4:$F$4992,4,FALSE) -> 0 | Y14: =E14&"|"&G14&"|"&I14&"|"&K14&"|"&M14&"|"&O14&"|"&Q14&"|"&S14&"|"&U14&"|"&W14 &" x "&D14 -> main-10||||||||| x 1
B15: 12 | C15: =(F15+H15+J15+L15+N15+P15+R15+T15+V15+X15)*D15 -> 1.5 | D15: 1 | E15: main-11 | F15: =VLOOKUP(E15,'Win Methods'!$C$4:$F$4992,4,FALSE) -> 1.5 | H15: =VLOOKUP(G15,'Win Methods'!$C$4:$F$4992,4,FALSE) -> 0 | J15: =VLOOKUP(I15,'Win Methods'!$C$4:$F$4992,4,FALSE) -> 0 | L15: =VLOOKUP(K15,'Win Methods'!$C$4:$F$4992,4,FALSE) -> 0 | N15: =VLOOKUP(M15,'Win Methods'!$C$4:$F$4992,4,FALSE) -> 0 | P15: =VLOOKUP(O15,'Win Methods'!$C$4:$F$4992,4,FALSE) -> 0 | R15: =VLOOKUP(Q15,'Win Methods'!$C$4:$F$4992,4,FALSE) -> 0 | T15: =VLOOKUP(S15,'Win Methods'!$C$4:$F$4992,4,FALSE) -> 0 | V15: =VLOOKUP(U15,'Win Methods'!$C$4:$F$4992,4,FALSE) -> 0 | X15: =VLOOKUP(W15,'Win Methods'!$C$4:$F$4992,4,FALSE) -> 0 | Y15: =E15&"|"&G15&"|"&I15&"|"&K15&"|"&M15&"|"&O15&"|"&Q15&"|"&S15&"|"&U15&"|"&W15 &" x "&D15 -> main-11||||||||| x 1
... B46: 43 | C46: =(F46+H46+J46+L46+N46+P46+R46+T46+V46+X46)*D46 -> 30 | D46: 1 | E46: main-42 | F46: =VLOOKUP(E46,'Win Methods'!$C$4:$F$4992,4,FALSE) -> 30 | H46: =VLOOKUP(G46,'Win Methods'!$C$4:$F$4992,4,FALSE) -> 0 | J46: =VLOOKUP(I46,'Win Methods'!$C$4:$F$4992,4,FALSE) -> 0 | L46: =VLOOKUP(K46,'Win Methods'!$C$4:$F$4992,4,FALSE) -> 0 | N46: =VLOOKUP(M46,'Win Methods'!$C$4:$F$4992,4,FALSE) -> 0 | P46: =VLOOKUP(O46,'Win Methods'!$C$4:$F$4992,4,FALSE) -> 0 | R46: =VLOOKUP(Q46,'Win Methods'!$C$4:$F$4992,4,FALSE) -> 0 | T46: =VLOOKUP(S46,'Win Methods'!$C$4:$F$4992,4,FALSE) -> 0 | V46: =VLOOKUP(U46,'Win Methods'!$C$4:$F$4992,4,FALSE) -> 0 | X46: =VLOOKUP(W46,'Win Methods'!$C$4:$F$4992,4,FALSE) -> 0 | Y46: =E46&"|"&G46&"|"&I46&"|"&K46&"|"&M46&"|"&O46&"|"&Q46&"|"&S46&"|"&U46&"|"&W46 &" x "&D46 -> main-42||||||||| x 1
B47: 44 | C47: =(F47+H47+J47+L47+N47+P47+R47+T47+V47+X47)*D47 -> 0.2 | D47: 1 | E47: main-0 | F47: =VLOOKUP(E47,'Win Methods'!$C$4:$F$4992,4,FALSE) -> 0.1 | G47: main-0 | H47: =VLOOKUP(G47,'Win Methods'!$C$4:$F$4992,4,FALSE) -> 0.1 | J47: =VLOOKUP(I47,'Win Methods'!$C$4:$F$4992,4,FALSE) -> 0 | L47: =VLOOKUP(K47,'Win Methods'!$C$4:$F$4992,4,FALSE) -> 0 | N47: =VLOOKUP(M47,'Win Methods'!$C$4:$F$4992,4,FALSE) -> 0 | P47: =VLOOKUP(O47,'Win Methods'!$C$4:$F$4992,4,FALSE) -> 0 | R47: =VLOOKUP(Q47,'Win Methods'!$C$4:$F$4992,4,FALSE) -> 0 | T47: =VLOOKUP(S47,'Win Methods'!$C$4:$F$4992,4,FALSE) -> 0 | V47: =VLOOKUP(U47,'Win Methods'!$C$4:$F$4992,4,FALSE) -> 0 | X47: =VLOOKUP(W47,'Win Methods'!$C$4:$F$4992,4,FALSE) -> 0 | Y47: =E47&"|"&G47&"|"&I47&"|"&K47&"|"&M47&"|"&O47&"|"&Q47&"|"&S47&"|"&U47&"|"&W47 &" x "&D47 -> main-0|main-0|||||||| x 1
B48: 45 | C48: =(F48+H48+J48+L48+N48+P48+R48+T48+V48+X48)*D48 -> 0.3 | D48: 1 | E48: main-0 | F48: =VLOOKUP(E48,'Win Methods'!$C$4:$F$4992,4,FALSE) -> 0.1 | G48: main-1 | H48: =VLOOKUP(G48,'Win Methods'!$C$4:$F$4992,4,FALSE) -> 0.2 | J48: =VLOOKUP(I48,'Win Methods'!$C$4:$F$4992,4,FALSE) -> 0 | L48: =VLOOKUP(K48,'Win Methods'!$C$4:$F$4992,4,FALSE) -> 0 | N48: =VLOOKUP(M48,'Win Methods'!$C$4:$F$4992,4,FALSE) -> 0 | P48: =VLOOKUP(O48,'Win Methods'!$C$4:$F$4992,4,FALSE) -> 0 | R48: =VLOOKUP(Q48,'Win Methods'!$C$4:$F$4992,4,FALSE) -> 0 | T48: =VLOOKUP(S48,'Win Methods'!$C$4:$F$4992,4,FALSE) -> 0 | V48: =VLOOKUP(U48,'Win Methods'!$C$4:$F$4992,4,FALSE) -> 0 | X48: =VLOOKUP(W48,'Win Methods'!$C$4:$F$4992,4,FALSE) -> 0 | Y48: =E48&"|"&G48&"|"&I48&"|"&K48&"|"&M48&"|"&O48&"|"&Q48&"|"&S48&"|"&U48&"|"&W48 &" x "&D48 -> main-0|main-1|||||||| x 1
B49: 46 | C49: =(F49+H49+J49+L49+N49+P49+R49+T49+V49+X49)*D49 -> 0.4 | D49: 1 | E49: main-1 | F49: =VLOOKUP(E49,'Win Methods'!$C$4:$F$4992,4,FALSE) -> 0.2 | G49: main-1 | H49: =VLOOKUP(G49,'Win Methods'!$C$4:$F$4992,4,FALSE) -> 0.2 | J49: =VLOOKUP(I49,'Win Methods'!$C$4:$F$4992,4,FALSE) -> 0 | L49: =VLOOKUP(K49,'Win Methods'!$C$4:$F$4992,4,FALSE) -> 0 | N49: =VLOOKUP(M49,'Win Methods'!$C$4:$F$4992,4,FALSE) -> 0 | P49: =VLOOKUP(O49,'Win Methods'!$C$4:$F$4992,4,FALSE) -> 0 | R49: =VLOOKUP(Q49,'Win Methods'!$C$4:$F$4992,4,FALSE) -> 0 | T49: =VLOOKUP(S49,'Win Methods'!$C$4:$F$4992,4,FALSE) -> 0 | V49: =VLOOKUP(U49,'Win Methods'!$C$4:$F$4992,4,FALSE) -> 0 | X49: =VLOOKUP(W49,'Win Methods'!$C$4:$F$4992,4,FALSE) -> 0 | Y49: =E49&"|"&G49&"|"&I49&"|"&K49&"|"&M49&"|"&O49&"|"&Q49&"|"&S49&"|"&U49&"|"&W49 &" x "&D49 -> main-1|main-1|||||||| x 1
B50: 47 | C50: =(F50+H50+J50+L50+N50+P50+R50+T50+V50+X50)*D50 -> 0.6 | D50: 1 | E50: main-0 | F50: =VLOOKUP(E50,'Win Methods'!$C$4:$F$4992,4,FALSE) -> 0.1 | G50: main-2 | H50: =VLOOKUP(G50,'Win Methods'!$C$4:$F$4992,4,FALSE) -> 0.5 | J50: =VLOOKUP(I50,'Win Methods'!$C$4:$F$4992,4,FALSE) -> 0 | L50: =VLOOKUP(K50,'Win Methods'!$C$4:$F$4992,4,FALSE) -> 0 | N50: =VLOOKUP(M50,'Win Methods'!$C$4:$F$4992,4,FALSE) -> 0 | P50: =VLOOKUP(O50,'Win Methods'!$C$4:$F$4992,4,FALSE) -> 0 | R50: =VLOOKUP(Q50,'Win Methods'!$C$4:$F$4992,4,FALSE) -> 0 | T50: =VLOOKUP(S50,'Win Methods'!$C$4:$F$4992,4,FALSE) -> 0 | V50: =VLOOKUP(U50,'Win Methods'!$C$4:$F$4992,4,FALSE) -> 0 | X50: =VLOOKUP(W50,'Win Methods'!$C$4:$F$4992,4,FALSE) -> 0 | Y50: =E50&"|"&G50&"|"&I50&"|"&K50&"|"&M50&"|"&O50&"|"&Q50&"|"&S50&"|"&U50&"|"&W50 &" x "&D50 -> main-0|main-2|||||||| x 1
